Workbook

Sheet READ ME
A1: STUDENT RECONSTRUCTION - ILLUSTRATIVE ONLY
A3: This file is a graduate coursework reconstruction of a real transaction, built by Mason J. Bennett (M.S. Finance, University of Arkansas) from publicly available filings. It is not affiliated with any party to the actual transaction and is published solely as a work sample. Assumptions diverge from actual deal terms where figures were not public. Not investment advice.
A5: masonjbennett.com | bennettmasonj@gmail.com

Sheet Deal Summary
A1: ELECTRONIC ARTS INC. (NASDAQ: EA) — TAKE-PRIVATE LBO DEAL SUMMARY
A3: TRANSACTION OVERVIEW
A4: Announcement Date | B4: September 29, 2025 | C4: EA Form 8-K, filed 9/29/2025 (SEC EDGAR)
A5: Parent Entity | B5: Oak-Eagle AcquireCo, Inc. (Delaware) | C5: DEFM14A, p.22
A6: Consortium Members | B6: PIF (majority), Silver Lake, Affinity Partners | C6: DEFM14A, p.1
A7: Transaction Type | B7: All-Cash Take-Private Merger (LBO) | C7: DEFM14A, p.3
A8: Offer Price per Share | B8: 210 | C8: Merger Agreement, Section 2.1
A9: Unaffected Share Price (9/25/2025) | B9: 168.32 | C9: DEFM14A, p.44; DEFA14A 12/15/25
A10: 52-Week High Prior to Deal (8/14/2025) | B10: 179.01 | C10: DEFA14A, filed 12/15/2025
A11: Enterprise Value (~) | B11: 55000 | C11: EA Form 8-K, filed 9/29/2025
A13: PREMIUM ANALYSIS
A14: Premium to Unaffected Price | B14: =(210-168.32)/168.32 -> 0.24762357 | C14: ($210 - $168.32) / $168.32
A15: Premium to 52-Week High | B15: =(210-179.01)/179.01 -> 0.17311882 | C15: ($210 - $179.01) / $179.01
A17: SHARES OUTSTANDING
A18: Common Shares Outstanding (Record Date 11/19/25) | B18: 250.1 | C18: DEFM14A, p.2 (250,106,129 shares)
A19: Diluted Shares (Goldman Sachs Estimate, mm) | B19: 258.7 | C19: DEFA14A: 249.3M common + 0.003M options + 8.0M RSUs + 1.4M PSUs
A20: Basic Shares FY2025 Period-End (mm) | B20: 257 | C20: FY25 10-K Press Release (Q4 Basic)
A21: Weighted Avg Diluted Shares FY2025 (mm) | B21: 264 | C21: FY25 10-K (Diluted EPS computation)
A23: FINANCING STRUCTURE
A24: Total Equity Commitment ($mm) | B24: 36400 | C24: Equity Commitment Letters, per DEFM14A p.5
A25: PIF Rollover (9.9% existing stake) | B25: =0.099*250.106129*210 -> 5199.7064 | C25: CONFIRMED: 9.9% × 250,106,129 shares × $210 = $5,199M (DEFM14A p.2)
A26: New Cash Equity (PIF + SL + Affinity) | B26: =36400-B25 -> 31200.294 | C26: Proxy discloses only aggregate $36.4B; sponsor splits not disclosed
A27: Debt Financing Committed ($mm) | B27: 20000 | C27: JPMorgan Debt Commitment Letter, DEFM14A p.5
A28: Debt Expected Funded at Close ($mm) | B28: 18000 | C28: DEFM14A p.5 ('$18B of which is expected to be funded')
A29: Equity % of Total Capitalization | B29: =36400/(36400+18000) -> 0.66911765 | C29: $36.4b / ($36.4b + $18b)
A30: Debt % of Total Capitalization | B30: =18000/(36400+18000) -> 0.33088235 | C30: $18b / ($36.4b + $18b)
A32: KEY ADVISORS & FEES
A33: Company Financial Advisor | B33: Goldman Sachs & Co. LLC | C33: DEFM14A p.4
A34: GS Advisory Fee | B34: ~$110 million ($10M at announcement + remainder at close) | C34: DEFM14A p.4
A35: Debt Financing Lead Arranger | B35: JPMorgan Chase Bank, N.A. | C35: DEFM14A p.5; amended 10/27/25
A36: Proxy Solicitor | B36: Innisfree M&A Incorporated | C36: DEFM14A cover letter
A37: EA Legal Advisors | B37: Wachtell, Lipton, Rosen & Katz | C37: DEFM14A p.34 (Background of Merger)
A38: Consortium Legal Advisors | B38: Davis Polk; Kirkland & Ellis; Sidley | C38: PitchBook Advisors section
A39: PIF Communications Advisor | B39: FGS Global | C39: PitchBook Advisors section
A40: HSR Act Filing | B40: November 3, 2025 | C40: DEFM14A p.8
A41: HSR Waiting Period Expired | B41: Not yet confirmed in primary sources | C41: No SEC disclosure of HSR expiry as of latest filings reviewed
A42: Stockholder Vote (Special Meeting) | B42: December 22, 2025 — Approved | C42: DEFM14A p.2
A43: CFIUS Review | B43: Ongoing as of April 2026 | C43: DEFM14A p.8
A44: Expected Close | B44: Q1 FY27 (by ~June 30, 2026) | C44: DEFM14A p.3
A46: DEAL PROTECTIONS
...

Sheet EV Bridge
A1: ENTERPRISE VALUE BRIDGE — ELECTRONIC ARTS INC.
A2: Reconciliation from offer price to implied Enterprise Value | Sources: DEFM14A, FY25 10-K
A4: EQUITY VALUE TO ENTERPRISE VALUE BRIDGE ($mm)
B5: Amount ($mm) | C5: Per Share ($) | D5: Source
A6: Offer Price per Share | C6: 210 | D6: $210.00 per Merger Agreement
A7: (x) Diluted Shares Outstanding (mm) | B7: 258.7 | D7: DEFA14A: 249.3M + 8.0M RSU + 1.4M PSU + 0.003M options
A8: Implied Equity Value | B8: =C6*B7 -> 54327 | C8: =C6 -> 210
A10: (+) Total Funded Debt (Senior Notes) | B10: 1884 | C10: =B10/B7 -> 7.2825667 | D10: FY25 10-K: $400M 2026 (matured 3/1/26, repaid in course) + $750M 2031 + $750M 2051. Face total $1.9B; LBO refinance only $1.5B.
A11: (+) Capital Lease Obligations | B11: 67 | C11: =B11/B7 -> 0.25898724 | D11: FY25 10-K Balance Sheet footnotes
A12: (+) Minority Interests / Preferred | B12: 0 | C12: =B12/B7 -> 0 | D12: None outstanding
A13: (-) Cash & Cash Equivalents | B13: -2136 | C13: =B13/B7 -> -8.256668 | D13: FY25 10-K Balance Sheet ($2,136M)
A14: (-) Short-Term Investments | B14: -112 | C14: =B14/B7 -> -0.4329339 | D14: FY25 10-K Balance Sheet ($112M)
A16: Implied Enterprise Value | B16: =B8+B10+B11+B12+B13+B14 -> 54030 | C16: =B16/B7 -> 208.85195
A18: DEAL MULTIPLE CHECK
A19: FY2025 EBITDA (OpInc + D&A) | B19: 1876 | C19: =B19/B7 -> 7.2516428 | D19: $1,520 + $356 (FY25 10-K)
A20: FY2025 Adj. EBITDA (incl SBC + Restr.) | B20: 2575 | C20: =B20/B7 -> 9.9536142 | D20: $1,876 + $642 SBC + $57 Restr. (FY25 10-K)
A21: FY2026E Adj. EBITDA (GS Mgmt Forecast) | B21: 2759 | C21: =B21/B7 -> 10.664863 | D21: GS/Mgmt Forecasts per DEFA14A
A22: FY2027E Adj. EBITDA (GS Mgmt Forecast) | B22: 3003 | C22: =B22/B7 -> 11.60804 | D22: GS/Mgmt Forecasts per DEFA14A
A24: EV / FY2025 EBITDA | B24: =B16/B19 -> 28.80064
A25: EV / FY2025 Adj. EBITDA | B25: =B16/B20 -> 20.982524
A26: EV / FY2026E Adj. EBITDA | B26: =B16/B21 -> 19.583182
A27: EV / FY2027E Adj. EBITDA | B27: =B16/B22 -> 17.992008
A29: LTM REFERENCE (through September 30, 2025)
A30: LTM Net Revenue | B30: 7288 | C30: =B30/B7 -> 28.171627 | D30: EA Q2 FY26 8-K (10/28/2025) — TTM through 9/30/25
A31: LTM Net Bookings | B31: 7130 | D31: EA Q2 FY26 8-K (10/28/2025)
A32: LTM Adj EBITDA (derived) | B32: ='EA Historicals'!B81 -> 1767 | D32: FY25 Adj EBITDA $2,084 + Q1+Q2 FY26 $744 − Q1+Q2 FY25 $1,061 (estimated)
A33: EV / LTM Net Revenue | B33: =B16/B30 -> 7.4135565
A34: EV / LTM Adj EBITDA | B34: =B16/B32 -> 30.57725
A36: RECONCILIATION TO "$55 BILLION" DEAL HEADLINE
A37: Balance-sheet Implied EV (row 16) | B37: =B16 -> 54030
A38: (+) Refinance Early-Tender Premium & Accrued Interest | B38: 75 | D38: Oak-Eagle tender pricing (2/25/2026)
A39: (+) Capitalized Debt Financing Fees + OID (est.) | B39: 500 | D39: Bloomberg (10/1/2025) — $500M JPMorgan fee
A40: (+) Advisor & Transaction Fees | B40: 415 | D40: DEFM14A p.4 — GS $110M + other ~$305M
A41: Reconciled EV | B41: =SUM(B37:B40) -> 55020
A42: Deal Headline (rounded) | B42: 55000
A43: Residual (unexplained rounding) | B43: =B42-B41 -> -20
A44: Note: $55B headline = balance-sheet EV + capitalized transaction costs + rounding. Primary-source EV per DEFM14A $54-55B range.

Sheet EA Historicals
A1: ELECTRONIC ARTS INC. — HISTORICAL FINANCIAL SUMMARY
A2: Fiscal Year Ends March 31 | All figures in $mm except per share | Sources: EA 10-K & Earnings Press Releases (SEC EDGAR)
B4: FY2022 | C4: FY2023 | D4: FY2024 | E4: FY2025 | F4: FY2026E (Guidance) | G4: Source
A5: INCOME STATEMENT
A6: Net Revenue | B6: 6991 | C6: 7426 | D6: 7562 | E6: 7463 | F6: 7300 | G6: 10-K
A7: Full Game | B7: 1993 | C7: 1937 | D7: 2015 | E7: 2002 | F7: N/A | G7: 10-K
A8: Live Services & Other | B8: 4998 | C8: 5489 | D8: 5547 | E8: 5461 | F8: N/A | G8: 10-K
A9: Cost of Revenue | B9: 1859 | C9: 1792 | D9: 1710 | E9: 1543 | F9: N/A | G9: 10-K / FY25 Press Release
A10: Gross Profit | B10: =B6-B9 -> 5132 | C10: =C6-C9 -> 5634 | D10: =D6-D9 -> 5852 | E10: =E6-E9 -> 5920 | F10: N/A
A11: Gross Margin % | B11: =B10/B6 -> 0.73408668 | C11: =C10/C6 -> 0.7586857 | D11: =D10/D6 -> 0.77386935 | E11: =E10/E6 -> 0.79324668 | F11: N/A
A13: Operating Expenses:
A14: Research & Development | B14: 2186 | C14: 2328 | D14: 2420 | E14: 2569 | F14: N/A | G14: 10-K
A15: Marketing & Sales | B15: 961 | C15: 978 | D15: 1019 | E15: 962 | F15: N/A | G15: 10-K
A16: General & Administrative | B16: 673 | C16: 727 | D16: 691 | E16: 745 | F16: N/A | G16: 10-K
A17: Amortization & Impairment of Intangibles | B17: 183 | C17: 158 | D17: 142 | E17: 67 | F17: N/A | G17: 10-K
A18: Restructuring | B18: 0 | C18: 111 | D18: 62 | E18: 57 | F18: N/A | G18: 10-K
A19: Total Operating Expenses | B19: =SUM(B14:B18) -> 4003 | C19: =SUM(C14:C18) -> 4302 | D19: =SUM(D14:D18) -> 4334 | E19: =SUM(E14:E18) -> 4400 | F19: N/A (not in guidance) | G19: EA does not provide cost-of-revenue guidance; OpInc derived in F20
A20: Operating Income (EBIT) | B20: =B10-B19 -> 1129 | C20: =C10-C19 -> 1332 | D20: =D10-D19 -> 1518 | E20: =E10-E19 -> 1520 | F20: 1529 | G20: Derived: Adj EBITDA $2,759 (DEFA14A) - SBC $680 (DEFA14A fn1) - ΔDR $550 (NB $7,850 - Rev $7,300)
A21: Operating Margin % | B21: =B20/B6 -> 0.16149335 | C21: =C20/C6 -> 0.17936978 | D21: =D20/D6 -> 0.20074054 | E21: =E20/E6 -> 0.20367145 | F21: =IF(F6=0,"N/A",F20/F6) -> 0.20945205
A23: Interest & Other Income (Expense), Net | B23: -48 | C23: -6 | D23: 71 | E23: 85 | F23: N/A | G23: 10-K
A24: Income Before Taxes | B24: =B20+B23 -> 1081 | C24: =C20+C23 -> 1326 | D24: =D20+D23 -> 1589 | E24: =E20+E23 -> 1605 | F24: N/A
A25: Provision for Income Taxes | B25: 292 | C25: 524 | D25: 316 | E25: 484 | F25: N/A | G25: 10-K
A26: Effective Tax Rate | B26: =B25/B24 -> 0.27012026 | C26: =C25/C24 -> 0.39517345 | D26: =D25/D24 -> 0.19886721 | E26: =E25/E24 -> 0.30155763 | F26: N/A
A27: Net Income | B27: 789 | C27: 802 | D27: 1273 | E27: 1121 | F27: 885 | G27: 10-K / FY26 Guidance
A29: Diluted EPS | B29: 2.76 | C29: 2.88 | D29: 4.68 | E29: 4.25 | F29: 3.44 | G29: 10-K / FY26 Guidance
A30: Diluted Shares (Wtd Avg, mm) | B30: 286 | C30: 278 | D30: 272 | E30: 264 | F30: 257 | G30: 10-K (FY26E from guidance)
A32: EBITDA BRIDGE
A33: Operating Income (from above) | B33: =B20 -> 1129 | C33: =C20 -> 1332 | D33: =D20 -> 1518 | E33: =E20 -> 1520 | F33: =F20 -> 1529
A34: (+) Depreciation, Amort, Accretion & Impairment | B34: 486 | C34: 536 | D34: 404 | E34: 356 | F34: N/A | G34: Cash Flow Statement (10-K)
A35: EBITDA | B35: =B33+B34 -> 1615 | C35: =C33+C34 -> 1868 | D35: =D33+D34 -> 1922 | E35: =E33+E34 -> 1876 | F35: N/A
A36: EBITDA Margin % | B36: =B35/B6 -> 0.2310113 | C36: =C35/C6 -> 0.25154861 | D36: =D35/D6 -> 0.25416556 | E36: =E35/E6 -> 0.25137344 | F36: N/A
A37: (+) Stock-Based Compensation | B37: 528 | C37: 548 | D37: 584 | E37: 642 | F37: N/A | G37: Cash Flow Statement (10-K)
A38: (+) Restructuring | B38: 0 | C38: 111 | D38: 62 | E38: 57 | F38: N/A | G38: 10-K (added back for Adj EBITDA)
A39: Adjusted EBITDA (incl SBC & Restructuring add-back) | B39: =B35+B37+B38 -> 2143 | C39: =C35+C37+C38 -> 2527 | D39: =D35+D37+D38 -> 2568 | E39: =E35+E37+E38 -> 2575 | F39: 2759 | G39: GS Mgmt Forecast per DEFA14A (note: different definition than historical calc)
A40: Adjusted EBITDA Margin % | B40: =B39/B6 -> 0.30653698 | C40: =C39/C6 -> 0.34029087 | D40: =D39/D6 -> 0.3395927 | E40: =E39/E6 -> 0.34503551 | F40: =IF(F6=0,"N/A",F39/F6) -> 0.37794521
A42: NET BOOKINGS
A43: Net Revenue | B43: =B6 -> 6991 | C43: =C6 -> 7426 | D43: =D6 -> 7562 | E43: =E6 -> 7463 | F43: =F6 -> 7300
A44: (+/-) Change in Deferred Net Revenue | B44: -92 | C44: -77 | D44: -132 | E44: -108 | F44: 550 | G44: Press Releases (FY24-25 verified; FY22-23 estimated)
A45: Total Net Bookings | B45: =B43+B44 -> 6899 | C45: =C43+C44 -> 7349 | D45: =D43+D44 -> 7430 | E45: =E43+E44 -> 7355 | F45: =F43+F44 -> 7850
A47: CASH FLOW STATEMENT
...

Sheet DCF (Goldman Sachs)
A1: DISCOUNTED CASH FLOW ANALYSIS — BASED ON GOLDMAN SACHS FAIRNESS OPINION
A2: Source: EA DEFM14A (filed 11/20/2025) and Supplemental DEFA14A (filed 12/15/2025) | SEC EDGAR
A4: DCF KEY ASSUMPTIONS (per Goldman Sachs)
A5: Valuation Date | B5: June 30, 2025 | C5: DEFM14A p.43
A6: Discounting Convention | B6: Mid-year | C6: DEFM14A p.43
A7: WACC Range | B7: 7.5% - 9.5% | C7: DEFM14A p.43 (CAPM-based)
A8: Terminal Perpetuity Growth Rate Range | B8: 2.0% - 3.0% | C8: DEFM14A p.43
A9: Cost of Equity (for Tax Asset discounting) | B9: 8.5% | C9: DEFM14A p.43 (CAPM)
A10: Annual Stock-Based Compensation (assumed) | B10: $680 million | C10: DEFA14A footnote (1)
A11: Diluted Shares (GS basis, mm) | B11: 258.7 | C11: DEFA14A (249.3 + 0.003 + 8.0 + 1.4)
A13: GS DCF IMPLIED VALUE PER SHARE | B13: $137 - $220 | C13: Per DEFA14A supplemental p.1
A14: Offer Price per Share | B14: $210.00 | C14: Merger Agreement
A16: MANAGEMENT FINANCIAL FORECASTS (disclosed in DEFM14A / DEFA14A)
B17: FY2026E | C17: FY2027E | D17: FY2028E | E17: FY2029E | F17: FY2030E | G17: FY2031E | H17: Source
A18: Net Bookings | B18: 7850 | C18: 8250 | D18: 10000 | E18: 10400 | F18: 10820 | G18: 11250 | H18: DEFA14A Table
A19: Adjusted EBITDA (GS Definition) | B19: 2759 | C19: 3003 | D19: 4200 | E19: 4060 | F19: 4328 | G19: 4500 | H19: DEFA14A Table
A20: (-) Stock-Based Compensation | B20: -680 | C20: -680 | D20: -680 | E20: -680 | F20: -680 | G20: -680 | H20: DEFA14A footnote (1)
A21: (-) Cash Taxes | B21: -355 | C21: -387 | D21: -612 | E21: -601 | F21: -651 | G21: -682 | H21: DEFA14A Table
A22: (+) Depreciation | B22: 209 | C22: 288 | D22: 300 | E22: 215 | F22: 220 | G22: 230 | H22: DEFA14A Table
A23: (+/-) Change in Net Working Capital | B23: 29 | C23: -33 | D23: -142 | E23: -33 | F23: -35 | G23: -35 | H23: DEFA14A Table
A24: (-) Capital Expenditures (implied) | B24: =B25-B19-B20-B21-B22-B23 -> -459 | C24: =C25-C19-C20-C21-C22-C23 -> -513 | D24: =D25-D19-D20-D21-D22-D23 -> -525 | E24: =E25-E19-E20-E21-E22-E23 -> -441 | F24: =F25-F19-F20-F21-F22-F23 -> -445 | G24: =G25-G19-G20-G21-G22-G23 -> -455 | H24: UFCF residual
A25: Unlevered Free Cash Flow | B25: 1503 | C25: 1678 | D25: 2541 | E25: 2520 | F25: 2737 | G25: 2878 | H25: DEFA14A Table
A27: Tax Asset Benefits (NOL / Reform) | B27: 46 | C27: 143 | D27: 141 | E27: 126 | F27: 104 | G27: 41 | H27: DEFA14A Table (see footnote 5)
A30: DCF SENSITIVITY — IMPLIED EQUITY VALUE PER SHARE ($)
A31: Goldman Sachs Disclosed Range: $137 - $220 per DEFA14A
A32: Grid reconstructed from disclosed corners ($137 low, $220 high); minor differences (<3%) reflect undisclosed net cash and tax asset timing inputs
A34: WACC \ TGR | B34: 2.0% | C34: 2.5% | D34: 3.0%
A35: 7.5% | B35: 182 | C35: 197 | D35: 214
A36: 8.0% | B36: 167 | C36: 179 | D36: 193
A37: 8.5% | B37: 154 | C37: 164 | D37: 176
A38: 9.0% | B38: 143 | C38: 152 | D38: 161
A39: 9.5% | B39: 134 | C39: 141 | D39: 149
A41: Note: The $210 offer price falls near the HIGH END of GS's $137-$220 DCF range (within top 5%).
A42: GS also conducted: (i) Future Share Price ($157-$236); (ii) Premia Paid Unaffected ($203-$255); (iii) Premia Paid 52-wk High ($163-$218).
A44: DCF RECONSTRUCTION NOTES:
A45: Terminal Value Method: | B45: Gordon Growth perpetuity (per DEFA14A) | C45: DEFM14A p.43 "perpetuity growth rates ranging from 2% to 3%"
A46: Explicit Period: | B46: FY26E - FY31E (6 years)
A47: Cash Flow Discount Date: | B47: June 30, 2025 | C47: DEFM14A p.43
A48: Tax Asset Discount Date: | B48: September 25, 2025 @ 8.5% cost of equity | C48: DEFM14A p.43 (separate discount)
A49: Diluted Shares: | B49: 258.7M | C49: 249.3 common + 0.003 options (TSM) + 8.0 RSU + 1.4 PSU target
...

Sheet Future Share Price
A1: ILLUSTRATIVE PRESENT VALUE OF FUTURE SHARE PRICE — GOLDMAN SACHS FAIRNESS OPINION
A2: Source: EA DEFM14A (filed 11/20/2025) and Supplemental DEFA14A (filed 12/15/2025) | SEC EDGAR
A4: KEY ASSUMPTIONS (per Goldman Sachs)
A5: Valuation / Discount Date | B5: June 30, 2025 | C5: DEFM14A p.43-44
A6: Multiple Basis | B6: EV / NTM Adjusted EBITDA | C6: DEFM14A p.43
A7: Multiple Range | B7: 14.0x - 16.0x | C7: DEFM14A p.43-44
A8: Forward Measurement Years | B8: FY2026, FY2027, FY2028 | C8: DEFM14A p.43
A9: Discount Rate (Cost of Equity) | B9: 8.5% | C9: DEFM14A (CAPM-based)
A10: Annual Dividend | B10: $0.76 per share | C10: DEFM14A (cumulative added back at PV)
A11: Forward Diluted Shares FY26 | B11: 255.6M | C11: DEFA14A supplemental
A12: Forward Diluted Shares FY27 | B12: 250.3M | C12: DEFA14A supplemental
A13: Forward Diluted Shares FY28 | B13: 243.3M | C13: DEFA14A supplemental
A14: Net Cash Assumption | B14: +$364M (illustrative) | C14: Approximate; GS figure not disclosed
A16: GS FUTURE SHARE PRICE IMPLIED VALUE PER SHARE
A17: GS Stated Range | B17: $157 - $236 | C17: DEFA14A p.2 (restated paragraph)
A18: Offer Price per Share | B18: 210 | C18: Merger Agreement §2.1
A20: FORWARD-YEAR NTM ADJUSTED EBITDA INPUTS ($mm)
A21: Year-End Date | B21: NTM = Next FY | C21: NTM EBITDA ($mm)
A22: End of FY2026 (March 31, 2026) | B22: FY27E | C22: 3003 | D22: DEFA14A Management Forecast
A23: End of FY2027 (March 31, 2027) | B23: FY28E | C23: 4200 | D23: DEFA14A Management Forecast
A24: End of FY2028 (March 31, 2028) | B24: FY29E | C24: 4060 | D24: DEFA14A Management Forecast
A26: FULL CALCULATION TABLE — 3x3 GRID
A27: Forward Year | B27: Multiple | C27: NTM EBITDA | D27: Implied EV | E27: (+) Net Cash | F27: Fwd Equity/sh | G27: PV @ 8.5% | H27: + Div PV
A28: FY26 | B28: 14 | C28: =C22 -> 3003 | D28: =B28*C28 -> 42042 | E28: 364 | F28: =(D28+E28)/255.6 -> 165.90767 | G28: =F28/(1.085^0.75) -> 156.06092 | H28: =G28+0.74 -> 156.80092
A29: FY26 | B29: 15 | C29: =C22 -> 3003 | D29: =B29*C29 -> 45045 | E29: 364 | F29: =(D29+E29)/255.6 -> 177.65649 | G29: =F29/(1.085^0.75) -> 167.11244 | H29: =G29+0.74 -> 167.85244
A30: FY26 | B30: 16 | C30: =C22 -> 3003 | D30: =B30*C30 -> 48048 | E30: 364 | F30: =(D30+E30)/255.6 -> 189.40532 | G30: =F30/(1.085^0.75) -> 178.16397 | H30: =G30+0.74 -> 178.90397
A31: FY27 | B31: 14 | C31: =C23 -> 4200 | D31: =B31*C31 -> 58800 | E31: 364 | F31: =(D31+E31)/250.3 -> 236.37235 | G31: =F31/(1.085^1.75) -> 204.92486 | H31: =G31+1.42 -> 206.34486
A32: FY27 | B32: 15 | C32: =C23 -> 4200 | D32: =B32*C32 -> 63000 | E32: 364 | F32: =(D32+E32)/250.3 -> 253.15222 | G32: =F32/(1.085^1.75) -> 219.47229 | H32: =G32+1.42 -> 220.89229
A33: FY27 | B33: 16 | C33: =C23 -> 4200 | D33: =B33*C33 -> 67200 | E33: 364 | F33: =(D33+E33)/250.3 -> 269.93208 | G33: =F33/(1.085^1.75) -> 234.01972 | H33: =G33+1.42 -> 235.43972
A34: FY28 | B34: 14 | C34: =C24 -> 4060 | D34: =B34*C34 -> 56840 | E34: 364 | F34: =(D34+E34)/243.3 -> 235.11714 | G34: =F34/(1.085^2.75) -> 187.86787 | H34: =G34+2.05 -> 189.91787
A35: FY28 | B35: 15 | C35: =C24 -> 4060 | D35: =B35*C35 -> 60900 | E35: 364 | F35: =(D35+E35)/243.3 -> 251.80436 | G35: =F35/(1.085^2.75) -> 201.20161 | H35: =G35+2.05 -> 203.25161
A36: FY28 | B36: 16 | C36: =C24 -> 4060 | D36: =B36*C36 -> 64960 | E36: 364 | F36: =(D36+E36)/243.3 -> 268.49157 | G36: =F36/(1.085^2.75) -> 214.53536 | H36: =G36+2.05 -> 216.58536
A38: SUMMARY 3×3 GRID — IMPLIED PRESENT VALUE PER SHARE ($)
A40: Year \ Multiple | B40: 14.0x | C40: 15.0x | D40: 16.0x
A41: FY2026 (Mar-26) | B41: =H28 -> 156.80092 | C41: =H29 -> 167.85244 | D41: =H30 -> 178.90397
A42: FY2027 (Mar-27) | B42: =H31 -> 206.34486 | C42: =H32 -> 220.89229 | D42: =H33 -> 235.43972
A43: FY2028 (Mar-28) | B43: =H34 -> 189.91787 | C43: =H35 -> 203.25161 | D43: =H36 -> 216.58536
A45: RECONCILIATION TO GOLDMAN'S STATED RANGE $157-$236:
A46: Low Corner | B46: FY26 / 14.0x | C46: $157 (EXACT MATCH)
A47: High Corner | B47: FY27 / 16.0x | C47: $235-236 (within $1)
...

Sheet CCA
A1: COMPARABLE COMPANY ANALYSIS — INDEPENDENT REFERENCE ANALYSIS
A2: Source: PitchBook Data, Inc. | Downloaded 04/12/2026 | NOTE: Goldman Sachs did NOT perform a Selected Companies Analysis in its fairness opinion.
A3: Note: Goldman Sachs did not perform a Selected Companies Analysis in its fairness opinion (DEFM14A pp. 41-55). This analysis is independent reference only.
A4: TTM FINANCIALS (Source: PitchBook)
A5: Company | B5: Ticker | C5: TTM Revenue ($K) | D5: TTM EBITDA ($K) | E5: EBITDA Margin | F5: Revenue Growth | G5: EBITDA Growth | H5: Net Income ($K) | I5: Net Margin | J5: CapEx/Sales
A6: Take-Two Interactive | B6: NAS:TTWO | C6: 6559100 | D6: 1576000 | E6: 0.103353 | F6: 0.203394 | G6: N/M | H6: 898531 | I6: -0.016881 | J6: 0.027458
A7: Ubisoft Entertainment | B7: PAR:UBI | C7: 2079146.8 | D7: 866908.58 | E7: 0.391703 | F7: -0.117793 | G7: -0.208853 | H7: 3823.882 | I7: 0.053207 | J7: N/A
A8: Capcom Co. | B8: TKS:9697 | C8: 1301663.8 | D8: 573001.56 | E8: 0.439554 | F8: 0.451725 | G8: 0.796859 | H8: 409128.56 | I8: 0.256223 | J8: 0.074277
A9: Square Enix Holdings | B9: TKS:9684 | C9: 2014640.7 | D9: 399653.11 | E9: 0.182933 | F9: -0.120153 | G9: 1.801516 | H9: 211075.75 | I9: 0.170709 | J9: 0.027828
A10: Krafton, Inc. | B10: KRX:259960 | C10: 2337506.1 | D10: 726845.88 | E10: 0.362745 | F10: 0.227613 | G10: -0.395638 | H10: 499619.53 | I10: 0.247053 | J10: 0.030666
A11: NetEase, Inc. | B11: HKG:09999 | C11: 15665231 | D11: 6043002 | E11: 0.385759 | F11: 0.069619 | G11: 0.177923 | H11: 4959753.3 | I11: 0.331573 | J11: 0.018224
A13: Electronic Arts (Target) | B13: NAS:EA | C13: 7306000 | D13: 2784000 | E13: 0.273063 | F13: -0.005581 | G13: -0.208831 | H13: 1875560 | I13: 0.154847 | J13: 0.030523
A15: TRADING MULTIPLES — as of April 13, 2026 (Source: PitchBook)
A16: Company | B16: Ticker | C16: EV/Revenue | D16: EV/EBITDA (Normalized) | E16: Price/Revenue | F16: Price/Earnings | G16: Dividend Yield
A17: Take-Two Interactive | B17: NAS:TTWO | C17: 5.739328 | D17: 55.531534 | E17: 5.461481 | F17: N/M | G17: 0
A18: Ubisoft Entertainment | B18: PAR:UBI | C18: 1.105987 | D18: 2.823532 | E18: 0.290593 | F18: 5.299684 | G18: 0
A19: Capcom Co. | B19: TKS:9697 | C19: 6.153648 | D19: 13.999767 | E19: 6.702968 | F19: 26.160661 | G19: 0.0122
A20: Square Enix Holdings | B20: TKS:9684 | C20: 2.055408 | D20: 11.235866 | E20: 2.850611 | F20: 16.698649 | G20: 0.0171
A21: Krafton, Inc. | B21: KRX:259960 | C21: 2.30343 | D21: 6.349994 | E21: 3.115172 | F21: 12.555366 | G21: 0.009432
A22: NetEase, Inc. | B22: HKG:09999 | C22: 3.220852 | D22: 8.349392 | E22: 4.678202 | F22: 14.113977 | G22: 0.026128
A24: SUMMARY STATISTICS (Comps Only, excl. EA)
B25: EV/Revenue | C25: EV/EBITDA | D25: P/Revenue | E25: EBITDA Margin | F25: Revenue Growth
A26: Mean (PitchBook) | B26: =AVERAGE(C17:C22) -> 3.4297755 | C26: =AVERAGE(D17:D22) -> 16.381681 | D26: =AVERAGE(E17:E22) -> 3.8498378 | E26: =AVERAGE(E6:E11) -> 0.31100783 | F26: =AVERAGE(F6:F11) -> 0.1190675
A27: Median | B27: =MEDIAN(C17:C22) -> 2.762141 | C27: =MEDIAN(D17:D22) -> 9.792629 | D27: =MEDIAN(E17:E22) -> 3.896687 | E27: =MEDIAN(E6:E11) -> 0.374252 | F27: =MEDIAN(F6:F11) -> 0.1365065
A28: 25th Percentile | B28: =PERCENTILE(C17:C22,0.25) -> 2.1174135 | C28: =PERCENTILE(D17:D22,0.25) -> 6.8498435 | D28: =PERCENTILE(E17:E22,0.25) -> 2.9167512 | E28: =PERCENTILE(E6:E11,0.25) -> 0.227886 | F28: =PERCENTILE(F6:F11,0.25) -> -0.07094
A29: 75th Percentile | B29: =PERCENTILE(C17:C22,0.75) -> 5.109709 | C29: =PERCENTILE(D17:D22,0.75) -> 13.308792 | D29: =PERCENTILE(E17:E22,0.75) -> 5.2656612 | E29: =PERCENTILE(E6:E11,0.75) -> 0.390217 | F29: =PERCENTILE(F6:F11,0.75) -> 0.22155825
A30: Median (excl. TTWO) | B30: =MEDIAN(C18:C22) -> 2.30343 | C30: =MEDIAN(D18:D22) -> 8.349392 | D30: =MEDIAN(E18:E22) -> 3.115172 | E30: Excludes Take-Two (55.5x outlier due to GTA VI cycle)
A31: PitchBook Comps Set Mean (for reference) | B31: 3.429775 | C31: 16.381681
A32: Electronic Arts (Deal Multiples) | B32: 6.814596 | C32: 24.956109 | D32: 7.055385 | E32: 45.610162 | F32: Source: PitchBook (at $210 deal price)
A33: Mean (excl. TTWO) | B33: =AVERAGE(C18:C22) -> 2.967865 | C33: =AVERAGE(D18:D22) -> 8.5517102 | D33: =AVERAGE(E18:E22) -> 3.5275092
A34: Note: LTM-basis output below applies peer multiples to EA trough-year EBITDA. Forward FY27E basis (rows 53-70) is used for Football Field valuation.
A35: EA IMPLIED VALUATION FROM CCA
A36: EA TTM EBITDA ($K, PitchBook) | B36: 2784000 | C36: Source: PitchBook TTM (Analyst Normalized; includes SBC + Restructuring add-back). GAAP-based LTM estimate ~$1,767M.
A37: EA Net Debt ($K, FY2025) | B37: -364000 | C37: FY25 10-K: Cash+STI $2,248M − Funded Debt $1,884M = $364M net cash
A38: Diluted Shares (K, GS basis) | B38: 258700 | C38: DEFA14A: 249.3M + 8.0M RSU + 1.4M PSU
B40: 25th Pctl | C40: Median | D40: 75th Pctl | E40: Mean
A41: EV/EBITDA Multiple Applied | B41: =C28 -> 6.8498435 | C41: =C27 -> 9.792629 | D41: =C29 -> 13.308792 | E41: =C26 -> 16.381681
A42: Implied Enterprise Value ($K) | B42: =B41*B36 -> 19069964 | C42: =C41*B36 -> 27262679 | D42: =D41*B36 -> 37051676 | E42: =E41*B36 -> 45606599
A43: (+) Net Cash ($K) | B43: =-$B$37 -> 364000 | C43: =-$B$37 -> 364000 | D43: =-$B$37 -> 364000 | E43: =-$B$37 -> 364000
A44: Implied Equity Value ($K) | B44: =B42+B43 -> 19433964 | C44: =C42+C43 -> 27626679 | D44: =D42+D43 -> 37415676 | E44: =E42+E43 -> 45970599
...

Sheet PTA
A1: PRECEDENT TRANSACTION ANALYSIS — INDEPENDENT REFERENCE ANALYSIS
A2: Sources: Press releases, 8-Ks, SEC filings | NOTE: Goldman Sachs did NOT perform a Selected Transactions Analysis in its fairness opinion.
A3: Note: Goldman Sachs did not perform a Selected Transactions Analysis in its fairness opinion (DEFM14A pp. 41-55). This analysis is independent reference only.
A5: Ann. Date | B5: Acquirer | C5: Target | D5: EV ($mm) | E5: LTM Rev ($mm) | F5: LTM EBITDA ($mm) | G5: EV/Rev | H5: EV/EBITDA | I5: Premium | J5: Type
A6: Sep 2025 | B6: PIF/Silver Lake/Affinity | C6: Electronic Arts (REFERENCE) | D6: 55000 | E6: 7288 | F6: 1767 | G6: =IF(E6=0,"N/A",D6/E6) -> 7.546652 | H6: =IF(F6=0,"N/A",D6/F6) -> 31.126203 | I6: =(210-168.32)/168.32 -> 0.24762357 | J6: Take-Private LBO
A7: Jan 18, 2022 | B7: Microsoft | C7: Activision Blizzard | D7: 68700 | E7: 8916 | F7: 3608 | G7: =D7/E7 -> 7.705249 | H7: =D7/F7 -> 19.04102 | I7: 0.453 | J7: Strategic Acq.
A8: Jan 10, 2022 | B8: Take-Two Interactive | C8: Zynga | D8: 12700 | E8: 2599 | F8: 529 | G8: =D8/E8 -> 4.8864948 | H8: =D8/F8 -> 24.007561 | I8: 0.64 | J8: Strategic Acq.
A9: Jan 31, 2022 | B9: Sony Interactive | C9: Bungie | D9: 3600 | E9: 600 | F9: 150 | G9: =IF(E9=0,"N/A",D9/E9) -> 6 | H9: =IF(F9=0,"N/A",D9/F9) -> 24 | I9: N/A (private) | J9: Strategic Acq.
A10: Feb 8, 2021 | B10: Electronic Arts | C10: Glu Mobile | D10: 2100 | E10: 540 | F10: 76 | G10: =D10/E10 -> 3.8888889 | H10: =D10/F10 -> 27.631579 | I10: 0.36 | J10: Strategic Acq.
A11: Jun 23, 2021 | B11: Electronic Arts | C11: Playdemic (from AT&T) | D11: 1400 | E11: 185 | F11: 65 | G11: =IF(E11=0,"N/A",D11/E11) -> 7.5675676 | H11: =IF(F11=0,"N/A",D11/F11) -> 21.538462 | I11: N/A (private) | J11: Strategic Acq.
A12: Jun 21, 2016 | B12: Tencent consortium | C12: Supercell | D12: 10200 | E12: 2326 | F12: 1053 | G12: =D12/E12 -> 4.3852107 | H12: =D12/F12 -> 9.6866097 | I12: N/A (private) | J12: Strategic Acq.
A13: Sep 21, 2020 | B13: Microsoft | C13: ZeniMax/Bethesda | D13: 7500 | E13: 450 | F13: 150 | G13: =D13/E13 -> 16.666667 | H13: =D13/F13 -> 50 | I13: N/A (private) | J13: Strategic Acq.
A14: Jul 3, 2024 | B14: EQT consortium | C14: Keywords Studios | D14: 2794 | E14: 839 | F14: 168 | G14: =D14/E14 -> 3.3301549 | H14: =D14/F14 -> 16.630952 | I14: 0.667 | J14: Take-Private
A16: Mean (excl. EA) | G16: =AVERAGE(G7:G14) -> 6.8037791 | H16: =AVERAGE(H7:H14) -> 24.067023 | I16: =IFERROR(AVERAGEIF(I7:I14,"<>N/A (private)"),"N/A") -> 0.53
A17: Median (excl. EA) | G17: =MEDIAN(G7:G14) -> 5.4432474 | H17: =MEDIAN(H7:H14) -> 22.769231 | I17: =IFERROR(MEDIAN(I7:I14),"N/A") -> 0.5465
A18: Mean (excl. EA & Bethesda) | G18: =AVERAGE(G7:G12,G14) -> 5.3947951 | H18: =AVERAGE(H7:H12,H14) -> 20.362312
A19: Median (excl. EA & Bethesda) | G19: =MEDIAN(G7:G12,G14) -> 4.8864948 | H19: =MEDIAN(H7:H12,H14) -> 21.538462
A21: EA IMPLIED VALUATION FROM PTA (LTM-based)
A22: EA LTM Adj EBITDA (through 9/30/25) | B22: 1767 | C22: ILLUSTRATIVE: FY25 $2,084 + Q1+Q2 FY26 − Q1+Q2 FY25
A23: EA Net Cash ($mm) | B23: 364 | C23: Cash+STI $2,248 − Funded Debt $1,884 (FY25 10-K)
A24: Diluted Shares (mm) | B24: 258.7 | C24: DEFA14A basis
A26: Multiple Applied | B26: Median (ex-EA) | C26: Median (ex-EA & Beth) | D26: Mean (ex-EA & Beth) | E26: 22.0x
A27: Multiple Value | B27: =H17 -> 22.769231 | C27: =H19 -> 21.538462 | D27: =H18 -> 20.362312 | E27: 22
A28: Implied EV ($mm) | B28: =B27*$B$22 -> 40233.231 | C28: =C27*$B$22 -> 38058.462 | D28: =D27*$B$22 -> 35980.205 | E28: =E27*$B$22 -> 38874
A29: (+) Net Cash | B29: =$B$23 -> 364 | C29: =$B$23 -> 364 | D29: =$B$23 -> 364 | E29: =$B$23 -> 364
A30: Implied Equity Value | B30: =B28+B29 -> 40597.231 | C30: =C28+C29 -> 38422.462 | D30: =D28+D29 -> 36344.205 | E30: =E28+E29 -> 39238
A31: Implied Price per Share | B31: =B30/$B$24 -> 156.92783 | C31: =C30/$B$24 -> 148.5213 | D31: =D30/$B$24 -> 140.48784 | E31: =E30/$B$24 -> 151.67375
A32: Offer Price | B32: 210 | C32: 210 | D32: 210 | E32: 210
A34: EA IMPLIED VALUATION FROM PTA (Forward FY27E-based)
A35: EA FY27E Adj EBITDA (per DEFA14A) | B35: 3003 | C35: Source: DEFA14A Management Forecasts
A37: Multiple Applied | B37: 16.0x (Low) | C37: 18.0x (Mid) | D37: 20.0x (High) | E37: 22.0x (Peak)
A38: Implied EV | B38: =16*$B$35 -> 48048 | C38: =18*$B$35 -> 54054 | D38: =20*$B$35 -> 60060 | E38: =22*$B$35 -> 66066
A39: (+) Net Cash | B39: =$B$23 -> 364 | C39: =$B$23 -> 364 | D39: =$B$23 -> 364 | E39: =$B$23 -> 364
A40: Implied Equity Value | B40: =B38+B39 -> 48412 | C40: =C38+C39 -> 54418 | D40: =D38+D39 -> 60424 | E40: =E38+E39 -> 66430
A41: Implied Price per Share | B41: =B40/$B$24 -> 187.13568 | C41: =C40/$B$24 -> 210.35176 | D41: =D40/$B$24 -> 233.56784 | E41: =E40/$B$24 -> 256.78392
A43: PTA RANGE FOR FOOTBALL FIELD (Forward FY27E, 16.0x - 20.0x):
A44: Low (16.0x FY27E) | B44: =B41 -> 187.13568
A45: High (20.0x FY27E) | B45: =D41 -> 233.56784
A47: Note: Private targets (Bungie, Playdemic, ZeniMax) have estimated financials (highlighted yellow).
A48: Note: Goldman Sachs did NOT perform a Selected Transactions Analysis. See DEFM14A p. 41-55.

Sheet Premia Paid
A1: PREMIA PAID ANALYSIS — FROM GOLDMAN SACHS FAIRNESS OPINION
A2: Source: DEFA14A filed 12/15/2025 (supplemental to DEFM14A) | SEC EDGAR | All data per Goldman Sachs / FactSet
A4: ANALYSIS 1: PREMIUM TO LAST UNDISTURBED CLOSING PRICE
A5: Universe: All-cash acquisitions of U.S. public targets with EV >= $5B, July 2015 - Sept 2025 (179 transactions)
A6: Source: FactSet as of September 25, 2025, per Goldman Sachs DEFA14A filing
A8: Year | B8: # of Transactions | C8: Median Premium
A9: 2015 | B9: 11 | C9: 0.4
A10: 2016 | B10: 17 | C10: 0.35
A11: 2017 | B11: 12 | C11: 0.24
A12: 2018 | B12: 20 | C12: 0.3
A13: 2019 | B13: 14 | C13: 0.42
A14: 2020 | B14: 10 | C14: 0.56
A15: 2021 | B15: 22 | C15: 0.23
A16: 2022 | B16: 24 | C16: 0.29
A17: 2023 | B17: 16 | C17: 0.56
A18: 2024 | B18: 19 | C18: 0.29
A19: Overall Period (179 txns)
A20: 25th Percentile Premium | B20: 0.2 | C20: Per Goldman Sachs / FactSet (DEFA14A)
A21: Median Premium | B21: 0.32 | C21: Per Goldman Sachs / FactSet (DEFA14A)
A22: 75th Percentile Premium | B22: 0.51 | C22: Per Goldman Sachs / FactSet (DEFA14A)
A24: IMPLIED EQUITY VALUE PER SHARE — UNDISTURBED PRICE BASIS
A25: EA Unaffected Share Price (9/25/2025) | B25: 168.32 | C25: Source: DEFA14A p.1
B27: 25th Pctl (20%) | C27: Median (32%) | D27: 75th Pctl (51%)
A28: Premium Applied | B28: 0.2 | C28: 0.32 | D28: 0.51
A29: Implied Price per Share | B29: =B25*(1+B28) -> 201.984 | C29: =B25*(1+C28) -> 222.1824 | D29: =B25*(1+D28) -> 254.1632
A30: GS Stated Range | B30: 203 | C30: to | D30: 255
A31: Offer Price | B31: 210 | C31: 210 | D31: 210
A34: ANALYSIS 2: PREMIUM TO 52-WEEK HIGH CLOSING PRICE
A35: Universe: All-cash acquisitions of U.S. public targets with EV >= $500M, Jan 2019 - Sept 2025 (~480 transactions)
A36: Source: FactSet as of September 25, 2025, per Goldman Sachs DEFA14A filing
A38: 25th Percentile Premium | B38: -0.09 | C38: Per Goldman Sachs / FactSet (DEFA14A)
A39: Median Premium | B39: 0.06 | C39: Per Goldman Sachs / FactSet (DEFA14A)
A40: 75th Percentile Premium | B40: 0.22 | C40: Per Goldman Sachs / FactSet (DEFA14A)
A42: EA 52-Week High Closing Price (8/14/2025) | B42: 179.01 | C42: Source: DEFA14A p.1
B44: 25th Pctl (-9%) | C44: Median (6%) | D44: 75th Pctl (22%)
A45: Premium Applied | B45: -0.09 | C45: 0.06 | D45: 0.22
A46: Implied Price per Share | B46: =B42*(1+B45) -> 162.8991 | C46: =B42*(1+C45) -> 189.7506 | D46: =B42*(1+D45) -> 218.3922
A47: GS Stated Range | B47: 163 | C47: to | D47: 218
A48: Offer Price | B48: 210 | C48: 210 | D48: 210

Sheet LBO Model
A1: LEVERAGED BUYOUT MODEL — ELECTRONIC ARTS INC.
A2: Deal: PIF / Silver Lake / Affinity | $55B EV | $210/share | Sources: DEFM14A, DEFA14A, Merger Agreement
A4: SOURCES & USES OF FUNDS ($mm)
A5: Sources | B5: Amount ($mm) | C5: % Total | E5: Uses | F5: Amount ($mm) | G5: % Total
A6: PIF Rollover (9.9% existing stake) | B6: =0.099*250.106129*210 -> 5199.7064 | C6: =IF($B$12=0,"",B6/$B$12) -> 0.09400904 | D6: CONFIRMED: DEFM14A p.2 — 24.76M sh × $210 | E6: Equity Purchase (250.1M × $210) | F6: =250.106129*210 -> 52522.287 | G6: =IF($F$12=0,"",F6/$F$12) -> 0.94955913
A7: Sponsor New Cash Equity (aggregate) | B7: 31201 | C7: =IF($B$12=0,"",B7/$B$12) -> 0.56410417 | D7: DERIVED: $36,400 aggregate − $5,199 rollover; individual sponsor splits NOT disclosed | E7: Cash-out Vested Options + RSU (est.) | F7: 300 | G7: =IF($F$12=0,"",F7/$F$12) -> 0.0054237497
A8: Subtotal Equity Financing | B8: =B6+B7 -> 36400.706 | C8: =IF($B$12=0,"",B8/$B$12) -> 0.65811321 | D8: CONFIRMED aggregate $36.4B — DEFM14A | E8: Refinance 2031 + 2051 Senior Notes (face) | F8: 1500 | G8: =IF($F$12=0,"",F8/$F$12) -> 0.027118748
A9: JPMorgan Debt Funded at Close | B9: 18010 | C9: =IF($B$12=0,"",B9/$B$12) -> 0.32561508 | D9: CONFIRMED: DEFM14A $20B committed, $18B funded at close | E9: + Tender early-payment & accrued interest | F9: 75
A10: EA Balance-Sheet Cash Contribution | B10: 900 | C10: =IF($B$12=0,"",B10/$B$12) -> 0.016271714 | D10: ILLUSTRATIVE: explains $20B / $18B gap per CreditSights | E10: Debt Financing Fees + OID (est. per Bloomberg) | F10: 500 | G10: =IF($F$12=0,"",F10/$F$12) -> 0.0090395828
E11: Advisor & Transaction Fees (GS $110M + other ~$305M) | F11: 415 | G11: =IF($F$12=0,"",F11/$F$12) -> 0.0075028537
A12: Total Sources | B12: =B6+B7+B9+B10 -> 55310.706 | C12: =B12/B12 -> 1 | E12: Total Uses | F12: =SUM(F6:F11) -> 55312.287
A13: Sources - Uses (should balance to ~$0): | B13: =B12-F12 -> -1.5806681
A14: Note: Items highlighted YELLOW are illustrative (not disclosed in DEFM14A).
A15: OPERATING MODEL & DEBT SCHEDULE ($mm) — LBO Close ~June 2026 (Start of FY27E = Y1)
B16: FY2026E | C16: FY2027E | D16: FY2028E | E16: FY2029E | F16: FY2030E | G16: FY2031E
A17: EBITDA (GS Adj Definition) | B17: 2759 | C17: 3003 | D17: 4200 | E17: 4060 | F17: 4328 | G17: 4500
A18: (-) Cash Taxes | B18: -355 | C18: -387 | D18: -612 | E18: -601 | F18: -651 | G18: -682
A19: (+) D&A | B19: 209 | C19: 288 | D19: 300 | E19: 215 | F19: 220 | G19: 230
A20: (-) CapEx (implied from GS) | B20: =B23-B17-B18-B19-B21-B22 -> -459 | C20: =C23-C17-C18-C19-C21-C22 -> -513 | D20: =D23-D17-D18-D19-D21-D22 -> -525 | E20: =E23-E17-E18-E19-E21-E22 -> -441 | F20: =F23-F17-F18-F19-F21-F22 -> -445 | G20: =G23-G17-G18-G19-G21-G22 -> -455
A21: (+/-) NWC Change | B21: 29 | C21: -33 | D21: -142 | E21: -33 | F21: -35 | G21: -35
A22: (-) SBC | B22: -680 | C22: -680 | D22: -680 | E22: -680 | F22: -680 | G22: -680
A23: Unlevered Free Cash Flow | B23: 1503 | C23: 1678 | D23: 2541 | E23: 2520 | F23: 2737 | G23: 2878
A25: DEBT SCHEDULE
A26: Beginning Total Debt | B26: Pre-Close (N/A) | C26: 18010 | D26: =C29 -> 17647.991 | E26: =D29 -> 16396.529 | F26: =E29 -> 15074.624 | G26: =F29 -> 13439.127
A27: (-) Mandatory Amortization | C27: -243.75 | D27: -243.75 | E27: -243.75 | F27: -243.75 | G27: -243.75
A28: (-) Optional Prepayment | C28: =-MAX(0,C23+C32+C27) -> -118.2593 | D28: =-MAX(0,D23+D32+D27) -> -1007.7113 | E28: =-MAX(0,E23+E32+E27) -> -1078.1556 | F28: =-MAX(0,F23+F32+F27) -> -1391.7472 | G28: =-MAX(0,G23+G32+G27) -> -1652.253
A29: Ending Total Debt | C29: =C26+C27+C28 -> 17647.991 | D29: =D26+D27+D28 -> 16396.529 | E29: =E26+E27+E28 -> 15074.624 | F29: =F26+F27+F28 -> 13439.127 | G29: =G26+G27+G28 -> 11543.124
A31: Blended Interest Rate (PitchBook wtd avg) | C31: 0.07307 | D31: 0.07307 | E31: 0.07307 | F31: 0.07307 | G31: 0.07307
A32: Interest Expense | C32: =-C26*C31 -> -1315.9907 | D32: =-D26*D31 -> -1289.5387 | E32: =-E26*E31 -> -1198.0944 | F32: =-F26*F31 -> -1101.5028 | G32: =-G26*G31 -> -981.99698
A33: Note: LBO debt schedule begins FY27E (= Year 1 post-close June 2026). FY26E is pre-close; UFCF accrues to public EA shareholders.
A34: CREDIT METRICS
A35: Total Debt / EBITDA | C35: =C29/C17 -> 5.8767868 | D35: =D29/D17 -> 3.9039356 | E35: =E29/E17 -> 3.7129615 | F35: =F29/F17 -> 3.1051586 | G35: =G29/G17 -> 2.5651386
A36: EBITDA / Interest (Coverage) | C36: =C17/(-C32) -> 2.281931 | D36: =D17/(-D32) -> 3.2569787 | E36: =E17/(-E32) -> 3.3887146 | F36: =F17/(-F32) -> 3.9291776 | G36: =G17/(-G32) -> 4.5824988
A39: RETURNS ANALYSIS — 5-YEAR HOLD (Y1=FY27E Apr-26 to Mar-27; Y5=FY31E exit Mar-31)
A40: Entry Equity ($mm) | B40: 36400 | C40: Source: Equity Commitment Letters
A41: Exit Year EBITDA ($mm, FY2031E) | B41: 4500 | C41: Source: GS Mgmt Forecasts
A43: Exit Multiple Sensitivity | B43: 14.0x | C43: 16.0x | D43: 18.0x | E43: 20.0x | F43: 22.0x
A44: Exit Enterprise Value | B44: =B41*14 -> 63000 | C44: =B41*16 -> 72000 | D44: =B41*18 -> 81000 | E44: =B41*20 -> 90000 | F44: =B41*22 -> 99000
A45: (-) Ending Debt (FY2031) | B45: =-G29 -> -11543.124 | C45: =-G29 -> -11543.124 | D45: =-G29 -> -11543.124 | E45: =-G29 -> -11543.124 | F45: =-G29 -> -11543.124
A46: Exit Equity Value | B46: =B44+B45 -> 51456.876 | C46: =C44+C45 -> 60456.876 | D46: =D44+D45 -> 69456.876 | E46: =E44+E45 -> 78456.876 | F46: =F44+F45 -> 87456.876
...

Sheet Football Field
A1: VALUATION FOOTBALL FIELD — IMPLIED EQUITY VALUE PER SHARE
A2: Offer Price: $210.00/share | Goldman Sachs Fairness Opinion (primary) + Independent Reference Analyses (supplementary)
A4: GOLDMAN SACHS FAIRNESS OPINION (PRIMARY) — per DEFM14A / DEFA14A
A5: Methodology | B5: Low ($) | C5: High ($) | D5: Midpoint ($) | E5: Offer ($210) | F5: Source / Notes
A6: 52-Week Trading Range (pre-deal) | B6: 116.53 | C6: 179.01 | D6: =(B6+C6)/2 -> 147.77 | E6: 210 | F6: DEFA14A: Low $116.53 (52-wk close); High $179.01 (8/14/2025 close)
A7: Illustrative DCF | B7: 137 | C7: 220 | D7: =(B7+C7)/2 -> 178.5 | E7: 210 | F7: DEFA14A p.1 (Goldman Sachs DCF analysis)
A8: Illustrative Future Share Price | B8: 157 | C8: 236 | D8: =(B8+C8)/2 -> 196.5 | E8: 210 | F8: DEFA14A p.2 (14x-16x EV/NTM Adj EBITDA, PV @ 8.5%)
A9: Premia Paid — vs. Unaffected ($168.32) | B9: 203 | C9: 255 | D9: =(B9+C9)/2 -> 229 | E9: 210 | F9: DEFA14A: 179 $5B+ US deals 2015-25, 20%-51% band applied to $168.32
A10: Premia Paid — vs. 52-Wk High ($179.01) | B10: 163 | C10: 218 | D10: =(B10+C10)/2 -> 190.5 | E10: 210 | F10: DEFA14A: ~480 $500M+ US deals 2019-25, -9% to +22% band applied to $179.01
A12: INDEPENDENT REFERENCE ANALYSES (NOT PART OF GOLDMAN FAIRNESS OPINION)
A13: Methodology | B13: Low ($) | C13: High ($) | D13: Midpoint ($) | E13: Offer ($210) | F13: Source / Notes
A14: CCA (EV/EBITDA, applied to FY27E) | B14: =CCA!B69 -> 163.9196 | C14: =CCA!B70 -> 233.56784 | D14: =(B14+C14)/2 -> 198.74372 | E14: 210 | F14: CCA Tab — 14.0x-20.0x applied to FY27E $3,003M EBITDA
A15: Precedent Transactions (EV/EBITDA, FY27E) | B15: =PTA!B44 -> 187.13568 | C15: =PTA!B45 -> 233.56784 | D15: =(B15+C15)/2 -> 210.35176 | E15: 210 | F15: PTA Tab — 16.0x-20.0x applied to FY27E $3,003M EBITDA
A16: LBO Affordability (20% IRR, 16x-20x exit) | B16: ='LBO Model'!B94 -> 163.53407 | C16: ='LBO Model'!B95 -> 191.49617 | D16: =(B16+C16)/2 -> 177.51512 | E16: 210 | F16: LBO Tab — Solve for entry price at 20% sponsor IRR target
A18: OFFER PRICE SUMMARY
A19: Offer Price per Share | B19: 210
A20: Premium to Unaffected ($168.32) | B20: =(B19-168.32)/168.32 -> 0.24762357
A21: Premium to 52-Wk High ($179.01) | B21: =(B19-179.01)/179.01 -> 0.17311882
A22: Premium to 52-Wk Low ($116.53) | B22: =(B19-116.53)/116.53 -> 0.80211104
A23: Enterprise Value | B23: ~$55 billion
A25: Goldman Sachs Fairness Opinion: "$210 per share is fair from a financial point of view" (delivered September 28, 2025)
A27: WHERE DOES $210 FALL?
A28: Methodology | B28: Range | D28: $210 Placement
A29: 52-Week Trading Range | B29: $116.53 - $179.01 | D29: $210 above high by 17.3%
A30: Illustrative DCF | B30: $137 - $220 | D30: $210 at 96th percentile (near top)
A31: Illustrative Future Share Price | B31: $157 - $236 | D31: $210 at 67th percentile (upper third)
A32: Premia Paid — Unaffected | B32: $203 - $255 | D32: $210 at 13th percentile (near low)
A33: Premia Paid — 52-Wk High | B33: $163 - $218 | D33: $210 at 85th percentile (upper third)
A34: CCA (FY27E EBITDA) | B34: ="$"&ROUND(CCA!B69,0)&" - $"&ROUND(CCA!B70,0) -> $164 - $234 | D34: See formulas
A35: PTA (FY27E EBITDA) | B35: ="$"&ROUND(PTA!B44,0)&" - $"&ROUND(PTA!B45,0) -> $187 - $234 | D35: See formulas
A36: LBO Affordability (20% IRR) | B36: ="$"&ROUND('LBO Model'!B94,0)&" - $"&ROUND('LBO Model'!B95,0) -> $164 - $191 | D36: $210 typically above affordability range
A38: Note: Chart data is in the 'Chart Data' tab.
A66: METHODOLOGY RATIONALE — WHY THESE FOUR ANALYSES?
A67: The football field above triangulates EA's implied per-share value through four standard valuation lenses: market-based (CCA), transaction-based (PTA), intrinsic-value (DCF), and sponsor-economics (LBO Affordability). Together these capture public-market trading multiples, recent gaming M&A precedent, fundamental cash-flow value, and the price at which a financial buyer can earn their hurdle return. Convergence across all four around the offer price ($210/share) is evidence that the deal is fairly priced; divergence flags where defenders and challengers will focus.
A69: Methodology | B69: Why this analysis? | D69: Why these specific metrics?
A70: Comparable Companies (CCA) | B70: Captures how the public market values comparable gaming and interactive-entertainment businesses today. Sets a floor reference for what a trading-multiple-based investor would pay; differences from the offer price reflect either control premium or peer-set distortion. | D70: EV/EBITDA, 14.0x – 20.0x applied to FY27E. EV/EBITDA is the gaming-industry standard because it is capital-structure-neutral and normalizes D&A differences across peers (vs. P/E or EV/Revenue). Forward FY27E is used because EA's LTM EBITDA is depressed by the gap-year before Battlefield 6 launch — applying peer multiples to a trough-year EBITDA would understate value. The 14x – 20x range reflects the gaming peer set (TTWO, RBLX, NTES, etc.) excluding TTWO's pre-GTA-VI outlier multiple.
A71: Precedent Transactions (PTA) | B71: Anchors valuation in what acquirers have actually paid for gaming companies in recent M&A. Captures control premium and strategic-buyer willingness-to-pay that public-market comps cannot. Sets a benchmark for what a competing bidder would have offered. | D71: EV/EBITDA, 16.0x – 20.0x applied to FY27E. Same EV/EBITDA rationale as CCA. Forward FY27E because gaming M&A bidders (Microsoft–Activision, Take-Two–Zynga, Carlyle–Jagex, Keywords–EQT, Bungie–Sony) underwrote based on synergized forward earnings rather than depressed LTM. The 16x – 20x range reflects the actual multiple range paid in recent large-cap gaming M&A.
A72: Discounted Cash Flow (DCF) | B72: Provides intrinsic-value anchor independent of market sentiment or M&A-cycle timing. This is the only fairness-opinion methodology Goldman Sachs performed for EA (per DEFM14A); the disclosed range is therefore the most authoritative single valuation reference. | D72: 7.5% – 9.5% WACC, 2.0% – 3.0% perpetuity growth rate. These are Goldman's disclosed assumptions (DEFA14A p.43). The WACC range reflects EA's CAPM-derived cost of capital with reasonable equity-risk-premium and beta sensitivity; the TGR range matches long-run software/interactive-entertainment industry growth expectations. Output range $137–$220 is reproduced in the DCF tab from these inputs.
A73: LBO Affordability | B73: Tests the deal from the financial sponsor's perspective: at what entry price can a PE buyer earn their target IRR over a standard hold period? This is the discipline that constrains LBO bids — sponsors cannot pay above their affordability range without sacrificing returns or relying on aggressive operating assumptions. | D73: 20% IRR target over a 5-year hold (Y1=FY27 through Y5=FY31), with exit at 16.0x – 20.0x EBITDA. 20% IRR is the standard large-cap PE sponsor hurdle. The 16x – 20x exit range aligns with the PTA range — sponsors expect to exit at multiples consistent with recent precedent. The analysis solves for the maximum entry price the sponsor can pay while still meeting the IRR hurdle, generating the affordability range $163.53 – $191.50.
A75: WHAT IS NOT IN THIS FOOTBALL FIELD AND WHY
...

Sheet Chart Data
A1: FOOTBALL FIELD CHART DATA
A2: Data structured for stacked bar chart | Goldman Opinion analyses + Independent Reference
A4: Methodology | B4: Low ($) | C4: High ($) | D4: Invisible Base | E4: Range (High - Low) | F4: Offer Price | G4: Group
A5: 52-Wk Trading Range | B5: 116.53 | C5: 179.01 | D5: =B5 -> 116.53 | E5: =C5-B5 -> 62.48 | F5: 210 | G5: Goldman Opinion
A6: Premia Paid — 52-Wk High | B6: 163 | C6: 218 | D6: =B6 -> 163 | E6: =C6-B6 -> 55 | F6: 210 | G6: Goldman Opinion
A7: Premia Paid — Unaffected | B7: 203 | C7: 255 | D7: =B7 -> 203 | E7: =C7-B7 -> 52 | F7: 210 | G7: Goldman Opinion
A8: Future Share Price | B8: 157 | C8: 236 | D8: =B8 -> 157 | E8: =C8-B8 -> 79 | F8: 210 | G8: Goldman Opinion
A9: DCF (Goldman) | B9: 137 | C9: 220 | D9: =B9 -> 137 | E9: =C9-B9 -> 83 | F9: 210 | G9: Goldman Opinion
A10: CCA (FY27E basis) | B10: ='Football Field'!B14 -> 163.9196 | C10: ='Football Field'!C14 -> 233.56784 | D10: =B10 -> 163.9196 | E10: =C10-B10 -> 69.648241 | F10: 210 | G10: Independent Reference
A11: Precedent Transactions (FY27E) | B11: ='Football Field'!B15 -> 187.13568 | C11: ='Football Field'!C15 -> 233.56784 | D11: =B11 -> 187.13568 | E11: =C11-B11 -> 46.432161 | F11: 210 | G11: Independent Reference
A12: LBO Affordability (20% IRR) | B12: ='Football Field'!B16 -> 163.53407 | C12: ='Football Field'!C16 -> 191.49617 | D12: =B12 -> 163.53407 | E12: =C12-B12 -> 27.962104 | F12: 210 | G12: Independent Reference
A14: LBO analysis (20% IRR at 16x – 20x exit) | B14: =B12 -> 163.53407 | C14: =C12 -> 191.49617 | D14: =B14 -> 163.53407 | E14: =C14-B14 -> 27.962104
A15: Discounted cash flow (7.5% – 9.5% WACC) | B15: =B9 -> 137 | C15: =C9 -> 220 | D15: =B15 -> 137 | E15: =C15-B15 -> 83
A16: Precedent transactions (EV / FY27E EBITDA) | B16: =B11 -> 187.13568 | C16: =C11 -> 233.56784 | D16: =B16 -> 187.13568 | E16: =C16-B16 -> 46.432161
A17: Comparable companies (EV / FY27E EBITDA) | B17: =B10 -> 163.9196 | C17: =C10 -> 233.56784 | D17: =B17 -> 163.9196 | E17: =C17-B17 -> 69.648241

Sheet Sources
A1: PRIMARY SOURCES & BIBLIOGRAPHY
A2: Every numerical input in this model traces to one of the sources below. Sources are organized by category. Direct quotations and SEC filings are authoritative; market-data sources (PitchBook, Bloomberg) are secondary. Retrieval dates are documented where relevant.
A4: # | B4: Source / Document | C4: Type | D4: Date | E4: URL / Citation Detail | F4: Used in (Tabs) | G4: Key Data Points Sourced | H4: Data Confidence | J4: Confidence Tier Legend
J5: CONFIRMED | K5: Direct from SEC filing or GS fairness opinion
A6: SEC FILINGS — TRANSACTION DOCUMENTS | J6: DERIVED | K6: Calculated from confirmed inputs (e.g., GS reconstruction, peer-derived multiples)
A7: 1 | B7: Form 8-K — Transaction Announcement | C7: 8-K | D7: Sept 29, 2025 | E7: https://www.sec.gov/cgi-bin/browse-edgar?action=getcompany&CIK=0000712515&type=8-K | F7: Deal Summary | G7: Transaction announcement; offer price $210/share; merger agreement details | H7: CONFIRMED | J7: MARKET DATA | K7: Bloomberg / PitchBook / FactSet / market price feeds
A8: 2 | B8: Definitive Merger Proxy Statement (DEFM14A) | C8: DEFM14A | D8: Nov 20, 2025 | E8: https://www.sec.gov/cgi-bin/browse-edgar?action=getcompany&CIK=0000712515&type=DEF | F8: All valuation tabs; LBO Model | G8: Diluted share count (258.7M); $36.4B equity commitment; $20B debt commitment; advisor fees; PIF rollover (24.76M shares) | H8: CONFIRMED | J8: REFERENCE | K8: Methodology / academic source (no numeric data sourced)
A9: 3 | B9: Supplemental Proxy Disclosure (DEFA14A) | C9: DEFA14A | D9: Dec 15, 2025 | E9: https://www.sec.gov/cgi-bin/browse-edgar?action=getcompany&CIK=0000712515&type=DEFA14A | F9: DCF; Future Share Price; Premia Paid; Football Field | G9: DCF range $137-$220; Future Share Price range $157-$236; Premia Paid analyses (Variant A/B); 52-week price reference points | H9: CONFIRMED | J9: ILLUSTRATIVE | K9: Estimated / not disclosed (rare; flagged in-source on each tab)
A10: 4 | B10: Merger Agreement (Exhibit 2.1 to 8-K) | C10: Merger Agt | D10: Sept 29, 2025 | E10: https://www.sec.gov/cgi-bin/browse-edgar?action=getcompany&CIK=0000712515&type=8-K | F10: Deal Summary; LBO Model | G10: Section 2.1 (offer price); Section 8.1(b) (outside date Sept 28, 2026); termination fees | H10: CONFIRMED
A12: SEC FILINGS — EA OPERATING & FINANCIAL DATA
A13: 5 | B13: Form 10-K (Annual Report, FY2025) | C13: 10-K | D13: May 2025 | E13: https://www.sec.gov/cgi-bin/browse-edgar?action=getcompany&CIK=0000712515&type=10-K | F13: EA Historicals; EV Bridge; DCF | G13: FY25 revenue $7,463M; OpInc $1,520M; EBITDA $1,876M; Adj EBITDA $2,575M; Net Bookings; Balance Sheet; Cash Flow Statement; Total Funded Debt $1,884M; Cash & STI $2,248M | H13: CONFIRMED
A14: 6 | B14: Form 10-K (Prior Year, FY2024) | C14: 10-K | D14: May 2024 | E14: https://www.sec.gov/cgi-bin/browse-edgar?action=getcompany&CIK=0000712515&type=10-K | F14: EA Historicals | G14: FY22-FY24 historical revenue, EBITDA, OpInc, balance sheet items; 5-year financial trends | H14: CONFIRMED
A15: 7 | B15: Form 10-Q (Q2 FY2026) | C15: 10-Q | D15: Oct 28, 2025 | E15: https://www.sec.gov/cgi-bin/browse-edgar?action=getcompany&CIK=0000712515&type=10-Q | F15: EA Historicals (LTM section); EV Bridge | G15: TTM through 9/30/25; Q1+Q2 FY26 results; LTM Net Revenue/Bookings; LTM Adj EBITDA derivation | H15: CONFIRMED
A16: 8 | B16: EA FY25 Earnings Press Release & Investor Presentation | C16: Press Release | D16: May 2025 | E16: https://ir.ea.com/financial-information/quarterly-results | F16: EA Historicals | G16: FY25 results announcement; Adj EBITDA reconciliation; segment-level net bookings | H16: CONFIRMED
A18: GOLDMAN SACHS FAIRNESS OPINION & SUPPORTING ANALYSES
A19: 9 | B19: Goldman Sachs Fairness Opinion (DEFM14A Exhibit) | C19: Fairness Opinion | D19: Sept 28, 2025 | E19: See DEFM14A pp.41-55 | F19: DCF; Future Share Price; Premia Paid; Deal Summary | G19: Fairness opinion language; methodology disclosure; key valuation outputs ($137-$220 DCF; $157-$236 FSP) | H19: CONFIRMED
A20: 10 | B20: Goldman Sachs DCF Analysis Detail | C20: DEFM14A p.43 | D20: Sept 28, 2025 | E20: https://www.sec.gov/cgi-bin/browse-edgar?action=getcompany&CIK=0000712515&type=DEF | F20: DCF | G20: WACC range 7.5%-9.5% (CAPM-based); TGR range 2.0%-3.0%; perpetuity growth method; mid-year discounting; tax asset PV (separate) | H20: DERIVED
A21: 11 | B21: Goldman Sachs Management Forecasts | C21: DEFA14A | D21: Dec 15, 2025 | E21: https://www.sec.gov/cgi-bin/browse-edgar?action=getcompany&CIK=0000712515&type=DEFA14A | F21: DCF; Future Share Price; LBO Model; CCA; PTA | G21: FY26-FY31 UFCF projections ($1,503M to $2,878M); FY27E EBITDA $3,003M; FY31E EBITDA $4,500M; Tax Asset benefits ($46M-$143M annually) | H21: CONFIRMED
A22: 12 | B22: Goldman Sachs Premia Paid Universe | C22: DEFA14A pp.1-3 | D22: Dec 15, 2025 | E22: https://www.sec.gov/cgi-bin/browse-edgar?action=getcompany&CIK=0000712515&type=DEFA14A | F22: Premia Paid; Football Field | G22: Variant A: 179 all-cash US deals $5B+ (2015-2025); 25th/Median/75th = 20%/32%/51%. Variant B: ~480 deals $500M+ (2019-2025); -9%/+6%/+22% | H22: CONFIRMED
A24: COMPARABLE COMPANIES (CCA) — PEER MARKET DATA
A25: 13 | B25: PitchBook Public Comps Set (Gaming) | C25: Database | D25: Apr 13, 2026 | E25: PitchBook Comparables Module (subscription) | F25: CCA | G25: Peer set EV/EBITDA and EV/Revenue multiples: TTWO 55.5x, NTES 12.4x, RBLX 17.3x, EA 21.0x, MSFT (gaming segment), Sony (G&NS) | H25: MARKET DATA
A26: 14 | B26: Take-Two Interactive — Form 10-K | C26: 10-K | D26: May 2025 | E26: https://ir.take2games.com/sec-filings | F26: CCA | G26: TTWO TTM EBITDA (depressed by pre-GTA-VI launch costs; outlier multiple reason) | H26: CONFIRMED
A27: 15 | B27: NetEase Inc. — Form 20-F | C27: 20-F | D27: Apr 2025 | E27: https://ir.netease.com/sec-filings | F27: CCA | G27: NetEase gaming segment financials; ADR pricing | H27: CONFIRMED
A28: 16 | B28: Roblox Corporation — Form 10-K | C28: 10-K | D28: Mar 2025 | E28: https://ir.roblox.com/sec-filings | F28: CCA | G28: Roblox EV/Bookings multiple; user-generated content peer reference | H28: CONFIRMED
A30: PRECEDENT TRANSACTIONS (PTA)
A31: 17 | B31: Microsoft / Activision Blizzard Acquisition | C31: Press Release / 8-K | D31: Jan 18, 2022 | E31: https://news.microsoft.com/2022/01/18/microsoft-to-acquire-activision-blizzard/ | F31: PTA | G31: Offer $95.00; ATVI unaffected $65.39 (1/14/22 close); premium 45.3%; EV/LTM EBITDA 19.04x; closed Oct 2023 | H31: CONFIRMED
A32: 18 | B32: Take-Two Interactive / Zynga Acquisition | C32: Press Release / 8-K | D32: Jan 10, 2022 | E32: https://www.take-two.com/news/ | F32: PTA | G32: Offer $9.86 (cash + stock); Zynga unaffected ~$6.02 (1/7/22); premium 64%; EV/LTM EBITDA 24.0x; closed May 2022 | H32: CONFIRMED
A33: 19 | B33: Electronic Arts / Glu Mobile Acquisition | C33: Press Release / 8-K | D33: Feb 8, 2021 | E33: https://www.ea.com/news/electronic-arts-completes-acquisition-of-glu-mobile | F33: PTA | G33: Offer $12.50 cash; Glu unaffected $9.19 (2/5/21 close); premium 36%; EV/LTM EBITDA 27.6x; closed Apr 2021 | H33: CONFIRMED
A34: 20 | B34: EQT / Keywords Studios Acquisition | C34: Rule 2.7 Announcement (UK Takeover Code) | D34: Jul 3, 2024 | E34: https://www.investegate.co.uk/announcement/keywords-studios | F34: PTA | G34: Offer £24.50 cash; Keywords unaffected £14.70 (May 17, 2024); premium 66.7%; EV/LTM EBITDA 16.6x; closed Q4 2024 | H34: CONFIRMED
A35: 21 | B35: Sony / Bungie Acquisition | C35: Press Release | D35: Jan 31, 2022 | E35: https://www.sie.com/en/corporate/release/2022/220131.html | F35: PTA | G35: EV $3.6B all-cash; private target (financials estimated); EV/Revenue ~6x; premium N/A (private) | H35: DERIVED
A36: 22 | B36: Embracer / Crystal Dynamics-Eidos-Square Enix West | C36: Press Release | D36: May 2, 2022 | E36: https://embracer.com/release/2022/ | F36: PTA | G36: EV $300M divestiture from Square Enix; private/divisional target; reference deal only | H36: DERIVED
A37: 23 | B37: EA / Playdemic Acquisition | C37: Press Release | D37: Jun 23, 2021 | E37: https://www.ea.com/news/ea-acquires-playdemic | F37: PTA | G37: EV $1.4B from Warner Bros.; private target (financials estimated); EV/Revenue ~14x | H37: DERIVED
A38: 24 | B38: Microsoft / ZeniMax (Bethesda) Acquisition | C38: Press Release / 8-K | D38: Sept 21, 2020 | E38: https://news.microsoft.com/2020/09/21/microsoft-to-acquire-zenimax/ | F38: PTA | G38: EV $7.5B all-cash; private target (financials estimated); reference for AAA-studio acquisition multiple | H38: DERIVED
A40: DEBT FINANCING & CAPITAL STRUCTURE
A41: 25 | B41: Bloomberg — Debt Commitment Coverage | C41: News (Subscription) | D41: Oct 1, 2025 | E41: Bloomberg Terminal | F41: LBO Model; Deal Summary | G41: JPMorgan lead arranger; $500M financing fees; $20B committed / $18B funded structure; tranche-level color (illustrative only) | H41: MARKET DATA
A42: 26 | B42: Oak-Eagle AcquireCo — Existing Bond Tender Offer | C42: Tender Offer Press Release | D42: Feb 10, 2026 | E42: https://www.prnewswire.com/news-releases/oak-eagle-tender-offer/ | F42: EV Bridge; Deal Summary | G42: $1.5B tender for 2031 and 2051 notes; early tender premium $75M; refinancing premium component of EV bridge | H42: CONFIRMED
A43: 27 | B43: Financial Times — Debt Syndication Coverage | C43: News (Subscription) | D43: Mar 2026 | E43: https://www.ft.com | F43: LBO Model; Deal Summary | G43: $8B bond component launch (March 2026); debt syndication progress; market color on pricing | H43: MARKET DATA
A44: 28 | B44: CreditSights / Fitch — EA Issuer Credit Profile | C44: Rating Agency Report | D44: Oct 2025 | E44: CreditSights Subscription / Fitch Ratings | F44: EV Bridge; LBO Model | G44: Pre-LBO credit profile; $20B-$18B commitment-vs-funded gap explanation; $900M EA cash contribution rationale (illustrative) | H44: MARKET DATA
A46: MARKET DATA & PRICING REFERENCES
A47: 29 | B47: EA Historical Stock Price (NASDAQ: EA) | C47: Market Data | D47: As of Sept 25, 2025 | E47: NASDAQ / Bloomberg / Yahoo Finance | F47: Deal Summary; Football Field; Premia Paid | G47: 52-week high $179.01 (8/14/2025 close); 52-week low $116.53; unaffected price $168.32 (last close before deal leak) | H47: MARKET DATA
...
