Workbook

Sheet READ ME
A1: STUDENT RECONSTRUCTION - ILLUSTRATIVE ONLY
A3: This file is a graduate coursework reconstruction of a real transaction, built by Mason J. Bennett (M.S. Finance, University of Arkansas) from publicly available filings. It is not affiliated with any party to the actual transaction and is published solely as a work sample. Assumptions diverge from actual deal terms where figures were not public. Not investment advice.
A5: masonjbennett.com | bennettmasonj@gmail.com

Sheet Summary
A1: JAGEX LBO MODEL — EXECUTIVE DASHBOARD
A2: CVC Capital Partners + Haveli Investments | Acquisition from The Carlyle Group | 14-May-2024
A3: University of Arkansas — Mason Bennett, , | April 2026
A5: DEAL AT A GLANCE
A6: Deal Value (USD) | B6: 1136 | D6: PitchBook (T3); officially undisclosed
A7: Deal Value (GBP) | B7: 900 | D7: FT, Sky News, PE-Insights press leaks
A8: Implied EV (USD) | B8: 1087 | D8: Calc: Deal − Cash + Debt + Leases
A9: Pro Forma EBITDA (USD) | B9: 75 | D9: PitchBook PF (T3); $18.6M add-backs vs reported
A10: Reported TTM EBITDA (USD) | B10: 56.4 | D10: PitchBook + CH Jagex Ltd FY23 (T1 cross-check)
A11: Total New Debt (USD) | B11: 164.15 | D11: PitchBook only — lender ID/amounts ILLUSTRATIVE
A12: Sponsor Equity (USD) | B12: 971.85 | D12: Residual: deal value − debt
A13: Deal / PF EBITDA | B13: 15.1 | D13: Implied entry multiple
A15: RETURNS SUMMARY (5-year hold, 15x EV/EBITDA exit)
A16: Layer | B16: Base | C16: Upside | D16: Downside | E16: Notes
A17: Sponsor MOIC (gross, 15x exit) | B17: ='LBO Model'!C110 -> 1.5717798 | C17: ='LBO Model'!D131 -> 1.931403 | D17: ='LBO Model'!E131 -> 1.1337043 | E17: From LBO Model row 110 (Base) and rows 131 (scenarios). Pre-fund mechanics.
A18: Sponsor MOIC (post-MIP) | B18: ='LBO Model'!C111 -> 1.5717798 | C18: ='LBO Model'!D131 -> 1.931403 | D18: ='LBO Model'!E131 -> 1.1337043 | E18: 10% MIP × 2.0x MOIC vesting hurdle. Base case does NOT clear hurdle.
A19: Sponsor IRR (5yr, post-MIP) | B19: ='LBO Model'!C112 -> 0.094657713 | C19: ='LBO Model'!D132 -> 0.14070825 | D19: ='LBO Model'!E132 -> 0.025415684 | E19: Base case below typical 20% PE target — deal is conservative.
A20: LP net IRR (after fund mechanics) | B20: =IF(('LBO Model'!$C$130+'LBO Model'!$C$209-MAX(0,'LBO Model'!$C$130+'LBO Model'!$C$209-'LBO Model'!$C$210)*'LBO Model'!$C$201)<=0,"N/A",(('LBO Model'!$C$130+'LBO Model'!$C$209-MAX(0,'LBO Model'!$C$130+'LBO Model'!$C$209-'LBO Model'!$C$210)*'LBO Model'!$C$201)/'LBO Model'!$C$9)^(1/5)-1) -> 0.080288182 | C20: =IF(('LBO Model'!$D$130+'LBO Model'!$C$209-MAX(0,'LBO Model'!$D$130+'LBO Model'!$C$209-'LBO Model'!$C$210)*'LBO Model'!$C$201)<=0,"N/A",(('LBO Model'!$D$130+'LBO Model'!$C$209-MAX(0,'LBO Model'!$D$130+'LBO Model'!$C$209-'LBO Model'!$C$210)*'LBO Model'!$C$201)/'LBO Model'!$C$9)^(1/5)-1) -> 0.11957342 | D20: =IF(('LBO Model'!$E$130+'LBO Model'!$C$209-MAX(0,'LBO Model'!$E$130+'LBO Model'!$C$209-'LBO Model'!$C$210)*'LBO Model'!$C$201)<=0,"N/A",(('LBO Model'!$E$130+'LBO Model'!$C$209-MAX(0,'LBO Model'!$E$130+'LBO Model'!$C$209-'LBO Model'!$C$210)*'LBO Model'!$C$201)/'LBO Model'!$C$9)^(1/5)-1) -> 0.0066517695 | E20: After 2-and-20 fund mechanics. Base ~8% — right at the 8% preferred return threshold.
A22: RETURNS ATTRIBUTION (Base case, 15x Y5 exit)
A23: Driver | B23: £M | C23: % of Total | D23: Investment Implication
A24: EBITDA growth | B24: ='LBO Model'!C148 -> 320.3845 | C24: ='LBO Model'!C155 -> 0.73461302 | D24: CVC thesis is OPERATIONAL — three-quarters of value from EBITDA growth.
A25: Multiple change (15.2x → 15.0x) | B25: ='LBO Model'!C149 -> -16.257601 | C25: ='LBO Model'!C156 -> -0.037277227 | D25: Slight contraction. Multiple expansion would require richer 2029 exit market.
A26: Deleveraging | B26: ='LBO Model'!C150 -> 132 | C26: ='LBO Model'!C157 -> 0.3026642 | D26: TL fully repaid by Y5 — but only 30% of return given conservative 2.2x leverage.
A27: Total equity value created | B27: ='LBO Model'!C151 -> 436.1269 | C27: 100.0% | D27: Reconciles to Exit Equity − Entry Equity within rounding (LBO Model C152).
A29: VALUATION CROSS-METHOD ($M)
A30: Method | B30: Low | C30: Midpoint | D30: High | E30: Deal Reference | F30: Notes
A31: CCA — original 8 comps | B31: ='Football Field'!B5 -> 299 | C31: ='Football Field'!D5 -> 616 | D31: ='Football Field'!C5 -> 933 | E31: 1136 | F31: 25th-75th EV/EBITDA × $75M PF
A32: CCA — tight peer (PF basis) | B32: =CCA!C53 -> 517.5 | C32: =(CCA!C97+CCA!C53)/2 -> 556.9521 | D32: =CCA!C97 -> 596.4042 | E32: 1136 | F32: Paradox/Frontier/Everplay; trough vs PF
A33: PTA — original 6 deals | B33: ='Football Field'!B6 -> 374 | C33: ='Football Field'!D6 -> 779 | D33: ='Football Field'!C6 -> 1184 | E33: 1136 | F33: 25th-75th of original PitchBook set
A34: PTA — expanded set (live-service take-privates) | B34: ='Football Field'!B9 -> 1192.5 | C34: ='Football Field'!D9 -> 1353.75 | D34: ='Football Field'!C9 -> 1515 | E34: 1136 | F34: Carlyle/Jagex 2021 + landmark take-privates
A35: DCF (8-12% WACC, 1.5-3.5% TGR) | B35: ='Football Field'!B7 -> 585 | C35: ='Football Field'!D7 -> 939 | D35: ='Football Field'!C7 -> 1293 | E35: 1136 | F35: WACC build: CAPM derives ~10.0% (Damodaran Jan-2026 inputs)
A36: LBO (15-20% IRR, 15-18x exit) | B36: ='Football Field'!B8 -> 779 | C36: ='Football Field'!D8 -> 927.5 | D36: ='Football Field'!C8 -> 1076 | E36: 1136 | F36: Implied range from sponsor return targets
A38: DEAL PRICE | C38: $1,136M | E38: 1136 | F38: Officially undisclosed; PitchBook back-calc from press £910M
A40: WHERE TO LOOK — TAB & CELL REFERENCES
A41: To find... | B41: Tab | C41: Cells
A42: Deal vehicle structure (Janus chain) | B42: Deal Summary | C42: B89:D94
A43: Carlyle-era debt (CH charges 0004/0005) | B43: Deal Summary | C43: B96:D100
A44: Pro Forma EBITDA bridge ($75M) | B44: Historicals | C44: B138:D166
A45: Tight peer analysis (Paradox/Frontier/Everplay) | B45: CCA | C45: B48:D61
A46: Peer regression analysis | B46: CCA | C46: B64:D102 | D46: Slope, R², margin-adjusted multiples
...

Sheet Deal Summary
B1: JAGEX LBO ANALYSIS — CVC/Haveli Acquisition
B2: Private-to-Private Secondary Buyout from Carlyle | Updated with PitchBook Data
B4: DEAL OVERVIEW (PitchBook Deal #6)
B5: Target | C5: Jagex Limited | D5: PitchBook; Carlyle PR Feb 9 2024
B6: HQ | C6: Cambridge, United Kingdom | D6: PitchBook Company Info
B7: Industry / SIC | C7: Entertainment Software / MMORPG | D7: PitchBook
B8: Financing Status | C8: Private Equity-Backed | D8: PitchBook Deal #6
B9: Business Status | C9: Generating Revenue | D9: PitchBook Deal #6
B10: CEO/Lead MGT (at deal) | C10: Philip Mansell (at deal); Jon Bellamy (from Mar 2025) | D10: PitchBook Deal #6; Jagex PR Mar 4 2025 (CEO transition)
B11: Employees | C11: 700 | D11: PitchBook Deal #6
B12: Flagship Product | C12: RuneScape + Old School RuneScape | D12: Jagex PR Feb 9 2024
B13: Lifetime Franchise Revenue | C13: $2 billion+ (updated Mar 2025) | D13: Jagex PR Mar 4 2025 ($1.5B+ at deal; $2B+ by Mar 2025)
B14: Active Subscribers | C14: 2.4 million | D14: Carlyle PR Feb 9 2024
B15: Lifetime Accounts | C15: 320+ million | D15: Carlyle PR Feb 9 2024
B17: TRANSACTION DETAILS (PitchBook)
B18: Deal Type | C18: Buyout/LBO, Secondary Buyout | D18: PitchBook Deal #6
B19: Announced Date | C19: 09-Feb-2024 | D19: PitchBook Deal #6
B20: Deal Date (Closed) | C20: 14-May-2024 | D20: PitchBook Deal #6
B21: Deal Status | C21: Completed | D21: PitchBook Deal #6
B22: Financing Source | C22: Private Equity | D22: PitchBook Deal #6
B23: Use of Proceeds | C23: Acquisition-related: LBO | D23: PitchBook Deal #6
B24: % Acquired | C24: 100.00% | D24: PitchBook Deal #6
B26: Buyer 1 | C26: CVC Capital Partners (Fund VIII) | D26: PitchBook Investors; Lead: Nicholas Clarry
B27: Buyer 2 | C27: Haveli Investments | D27: PitchBook Investors; Lead: Brian Sheth
B28: Seller | C28: The Carlyle Group (Full Exit) | D28: PitchBook Sellers/Exiters
B29: Seller Funds | C29: Carlyle Partners VII + Carlyle Europe Tech Partners IV | D29: PitchBook Sellers/Exiters
B30: % Company Sold | C30: 100.00% | D30: PitchBook Sellers/Exiters
B32: ADVISORS (PitchBook)
B33: Goldman Sachs | C33: Advisor: General — CVC Capital Partners | D33: PitchBook Advisors #1
B34: Goldman Sachs | C34: Advisor: General — Haveli Investments | D34: PitchBook Advisors #2
B35: Aream & Co. | C35: Advisor: General — Jagex (Seller-side) | D35: PitchBook Advisors #3
B36: Liberty Corporate Finance | C36: Advisor: General — Jagex | D36: PitchBook Advisors #4
B37: Morgan Stanley | C37: Advisor: General — Jagex | D37: PitchBook Advisors #5
B38: Apollo Global Mgmt | C38: Debt Financing — Jagex | D38: PitchBook Advisors #6
B39: Oaktree Capital Mgmt | C39: Debt Financing — Jagex | D39: PitchBook Advisors #7
B40: Latham & Watkins | C40: Legal Advisor — CVC (Lead: Suneel Basson-Bhatoa) | D40: PitchBook Advisors #8
B41: Kirkland & Ellis | C41: Legal Advisor — Carlyle (Lead: David Higgins) | D41: PitchBook Advisors #9
B43: DEAL VALUATION METRICS (PitchBook + Press)
B44: Deal Amount (USD) | C44: $1,136M | D44: PitchBook Deal #6: $1,136,109K
B45: Post Valuation (USD) | C45: $1,136M | D45: PitchBook Deal #6
...

Sheet EV Bridge
B1: JAGEX — ENTERPRISE VALUE BRIDGE
B2: Private-to-Private: No share price mechanics. EV derived from deal structure.
B3: ($ in thousands, per PitchBook)
B5: EV BRIDGE RECONCILIATION
B6: Deal Amount (Equity Value paid by CVC/Haveli) | C6: 1136109 | D6: PitchBook Deal #6: "Deal Size: 1,136,109.21"
B7: (-) Target Cash & Equivalents (FY2023) | C7: -50239 | D7: PitchBook BS: Cash & CE at 31-Dec-2023
B8: (+) Target Total Debt (FY2023) | C8: 0 | D8: PitchBook BS: Total Debt = $0 (zero funded debt)
B9: (+) Capital Lease Obligations | C9: 2238 | D9: PitchBook BS: Current cap lease $2,238K (FY2023)
B10: (-) Short-Term Investments | C10: 0 | D10: PitchBook BS: none reported FY2023
B12: Implied Enterprise Value (calculated) | C12: =SUM(C6:C10) -> 1088108 | D12: Deal Amount - Cash + Debt + Leases
B13: Implied Enterprise Value (PitchBook) | C13: 1086869 | D13: PitchBook Deal #6: "Implied EV: 1,086,869.49"
B15: Reconciliation Check | C15: =C12-C13 -> 1239 | D15: Calculated vs PitchBook
B18: NOTES ON PRIVATE-TO-PRIVATE EV BRIDGE
B19: Unlike public-to-private deals, there is no (Price x Shares) calculation. The Deal Amount IS the equity value paid.
B20: PitchBooks Implied EV ($1,086,869K) = Deal Amount ($1,136,109K) minus adjustments for cash, debt, and other items.
B21: The ~$49M difference between Deal Amount and Implied EV is primarily the targets cash balance ($50,239K), net of minor lease adjustments.
B22: Reconciliation difference (if any) reflects rounding or items PitchBook includes that are not individually disclosed (e.g., minority interests, pension adjustments).
B23: Note: At the OPCO level (Jagex Ltd #03982706) there was no funded debt under Carlyle 2021-2024 — accurate per Companies House Jagex Ltd accounts. However, the GROUP (June UK Bidco / June UK Finco) carried debt secured by Companies House charges 0004 (Lucid Trustee, 7 May 2021) and 0005 (Kroll Trustee, 20 Jun 2023), both satisfied at deal close 15 May 2024. The CVC/Haveli acquisition financing (~$164M per PitchBook) is now secured at Janus Bidco level (charge 0006, 10 Sep 2024, Kroll Trustee).

Sheet Historicals
B1: JAGEX LIMITED — HISTORICAL FINANCIALS (PitchBook)
B2: Amounts in $000s USD (PitchBook) | Source: PitchBook Data, Inc. | All data "Original" per PitchBook
B3: Downloaded 15-Apr-2026 for Mason Bennett, University of Arkansas (Students)
B5: INCOME STATEMENT
C6: FY2019 | D6: FY2020 | E6: FY2021 | F6: FY2022 | G6: FY2023 | H6: FY2024 | I6: Source
B7: Year End | C7: 31-Dec-2019 | D7: 31-Dec-2020 | E7: 31-Dec-2021 | F7: 31-Dec-2022 | G7: 31-Dec-2023 | H7: 31-Dec-2024
B8: Total Revenue | C8: 138511 | D8: 153772 | E8: 171704 | F8: 169367 | G8: 188773 | H8: 193483 | I8: PitchBook IS (Jagex Limited consolidated group: Jagex + Pipeworks + Gamepires); may differ from Jagex Ltd standalone filings at Companies House. FY19 derived from CoR+GP.
B9: Cost of Revenue | C9: 49900 | D9: 16924 | E9: 22539 | F9: 20751 | G9: 27518 | H9: 27313 | I9: PitchBook IS
B10: Gross Profit | C10: 88611 | D10: 136848 | E10: 149164 | F10: 148616 | G10: 161255 | H10: 166170 | I10: PitchBook IS
B12: Wages & Salaries | C12: - | D12: 40432 | E12: 39951 | F12: 35716 | G12: 40678 | H12: 44360 | I12: PitchBook IS
B13: Directors' Remuneration | C13: 7301 | D13: 5467 | E13: 6406 | F13: 4647 | G13: 4095 | H13: 3176 | I13: PitchBook IS
B14: Auditor Fees | C14: 153 | D14: 95 | E14: 1369 | F14: 1352 | G14: 587 | H14: 825 | I14: PitchBook IS
B15: Depreciation | C15: - | D15: 2072 | E15: 2590 | F15: 2243 | G15: 3336 | H15: 3125 | I15: PitchBook IS
B16: D&A (incl amort) | C16: 2129 | D16: 2129 | E16: 4185 | F16: 10482 | G16: 9009 | H16: 8136 | I16: PitchBook IS
B17: Total Opex (incl CoR) | C17: - | D17: 103754 | E17: 120819 | F17: 126677 | G17: 141335 | H17: 163270 | I17: PitchBook IS
B19: Total Operating Profit/(Loss) | C19: 58308 | D19: 50018 | E19: 50884 | F19: 42690 | G19: 47438 | H19: 30213 | I19: PitchBook IS
B21: Interest Expense | C21: - | D21: 353 | E21: 322 | F21: 291 | G21: 4761 | H21: 2451 | I21: PitchBook IS
B22: Interest Income | C22: 540 | D22: 64 | E22: 21 | F22: 2994 | G22: 6143 | H22: 10535 | I22: PitchBook IS
B23: Net Interest (Income)/Expense | C23: - | D23: 288 | E23: 301 | F23: -2703 | G23: -1383 | H23: -8084 | I23: PitchBook IS; negative=net income
B25: Pretax Income | C25: 49730 | D25: 49730 | E25: 50583 | F25: 45393 | G25: 48820 | H25: 38297 | I25: PitchBook IS
B26: Provision for Income Tax | C26: 5233 | D26: 5890 | E26: 2285 | F26: -1522 | G26: -102 | H26: 2735 | I26: PitchBook IS
B28: Net Income to Common | C28: 43840 | D28: 43840 | E28: 48298 | F28: 46915 | G28: 48922 | H28: 35562 | I28: PitchBook IS
B30: Profitability Metrics:
B31: EBITDA | C31: - | D31: 52147 | E31: 55069 | F31: 53172 | G31: 56447 | H31: 38349 | I31: PitchBook IS
B32: EBIT | C32: - | D32: 50018 | E32: 50884 | F32: 42690 | G32: 47438 | H32: 30213 | I32: PitchBook IS
B33: Gross Dividends | C33: 97492 | D33: 0 | E33: 16612 | F33: 0 | G33: 2953 | H33: 0 | I33: PitchBook IS
B35: KEY MARGINS & GROWTH (PitchBook Ratios)
B36: Gross Margin | C36: - | D36: 0.8899 | E36: 0.8687 | F36: 0.8775 | G36: 0.8542 | H36: 0.8588 | I36: PitchBook Ratios
B37: EBITDA Margin | C37: - | D37: 0.3391 | E37: 0.3207 | F37: 0.3139 | G37: 0.299 | H37: 0.1982 | I37: PitchBook Ratios
B38: EBIT Margin | C38: - | D38: 0.3253 | E38: 0.2963 | F38: 0.2521 | G38: 0.2513 | H38: 0.1562 | I38: PitchBook Ratios
B39: Net Profit Margin | C39: - | D39: 0.285 | E39: 0.2813 | F39: 0.277 | G39: 0.2592 | H39: 0.1838 | I39: PitchBook Ratios
B41: Revenue % Growth (GBP basis) | C41: - | D41: - | E41: 0.0409 | F41: 0.1006 | G41: 0.1051 | H41: -0.0029 | I41: PitchBook Ratios
B42: EBITDA % Growth | C42: - | D42: - | E42: -0.0156 | F42: 0.0773 | G42: 0.0526 | H42: -0.3391 | I42: PitchBook Ratios
B44: Effective Tax Rate | C44: - | D44: 0.1185 | E44: 0.0452 | F44: -0.0335 | G44: -0.0021 | H44: 0.0714 | I44: Calculated: Tax/Pretax. Low rates reflect UK Video Games Tax Relief (VGTR)
B47: BALANCE SHEET
C48: FY2019 | D48: FY2020 | E48: FY2021 | F48: FY2022 | G48: FY2023 | H48: FY2024 | I48: Source
B49: Assets:
B50: Cash & Equivalents | C50: 19507 | D50: 60445 | E50: 61599 | F50: 35465 | G50: 50239 | H50: 27250 | I50: PitchBook BS
B51: Trade/Accts Receivable | C51: - | D51: - | E51: - | F51: - | G51: - | H51: -
B52: Other Current Assets | C52: 16497 | D52: 35150 | E52: 45470 | F52: 88423 | G52: - | H52: 147068 | I52: PitchBook BS
...

Sheet CCA
B1: JAGEX — COMPARABLE COMPANY ANALYSIS (CCA)
B2: PitchBook Data, Inc. | Downloaded 15-Apr-2026 | All amounts in USD millions
B3: Created for: Mason Bennett, University of Arkansas (Students)
B5: FINANCIALS (TTM) | C5: Jagex | D5: Square Enix | E5: NCsoft | F5: Stillfront | G5: Gravity | H5: Pearl Abyss | I5: Paradox Int. | J5: Everplay | K5: Frontier Dev | L5: Source
B6: Ticker | C6: Private | D6: TKS:9684 | E6: KRX:036570 | F6: STO:SF | G6: NAS:GRVY | H6: KRX:263750 | I6: STO:PDX | J6: LON:EVPL | K6: LON:FDEV | L6: PitchBook
B7: Revenue ($M) | C7: 193.5 | D7: 2014.6 | E7: 1058.9 | F7: 582.4 | G7: 393.9 | H7: 256.9 | I7: 223.1 | J7: 218.6 | K7: 134.9 | L7: PitchBook TTM
B8: Revenue Growth % | C8: -0.003 | D8: -0.12 | E8: -0.045 | F8: -0.153 | G8: 0.119 | H8: 0.068 | I8: -0.004 | J8: -0.004 | K8: 0.158
B9: EBITDA ($M) | C9: 38.3 | D9: 314.4 | E9: 354.8 | F9: -62.2 | G9: 63.9 | H9: 5.4 | I9: 98.7 | J9: 85.9 | K9: 52.6 | L9: PitchBook TTM
B10: Norm. EBITDA Margin | C10: 0.198 | D10: 0.183 | E10: 0.06 | F10: 0.365 | G10: 0.171 | H10: 0.017 | I10: 0.443 | J10: 0.292 | K10: 0.369
B11: Net Income ($M) | C11: 35.6 | D11: 152.1 | E11: N/A | F11: -244 | G11: 47.4 | H11: N/A | I11: 12.8 | J11: 35.9 | K11: 26.2
B12: CapEx / Sales | C12: 0 | D12: 0.028 | E12: 0.076 | F12: 0.091 | G12: 0.011 | H12: 0.012 | I12: 0.299 | J12: 0.288 | K12: 0.279
B14: TRADING MULTIPLES (16-Apr-2026)
B15: EV / Revenue | D15: 2.13 | E15: 1.99 | F15: 1.1 | G15: N/A | H15: 8.26 | I15: 5.63 | J15: 2.02 | K15: 1.12 | L15: PitchBook
B16: EV / EBITDA (Normalized) | D16: 11.64 | E16: 33.02 | F16: 3.02 | G16: N/A | H16: 477.24 | I16: 12.72 | J16: 6.9 | K16: 3.03 | L16: PitchBook; Pearl Abyss 477x excluded as outlier
B17: Price / Revenue | D17: 2.88 | E17: 3.08 | F17: 0.42 | G17: 1.07 | H17: 9.36 | I17: 6.22 | J17: 2.32 | K17: 1.51
B18: Price / Earnings | D18: 16.87 | E18: 117.25 | F18: 22.25 | G18: 8.43 | H18: N/A | I18: 109.35 | J18: 10.38 | K18: 8.47
B20: SUMMARY STATISTICS
C21: EV / Revenue | D21: EV / EBITDA | E21: Notes
C22: (7 comps) | D22: (6 comps, excl. Pearl Abyss 477x)
B23: Mean | C23: 3.1785714 | D23: 11.721667
B24: Median | C24: 2.02 | D24: 9.27
B25: 25th Percentile | C25: 1.555 | D25: 3.9975
B26: 75th Percentile | C26: 3.88 | D26: 12.45
B28: IMPLIED JAGEX VALUATION ($M)
C29: EV/Revenue | D29: EV/EBITDA (Rptd) | E29: EV/EBITDA (PF $75M)
B30: 25th Percentile | C30: 300.8925 | D30: 153.10425 | E30: 299.8125
B31: Median | C31: 390.87 | D31: 355.041 | E31: 695.25
B32: Mean | C32: 615.05357 | D32: 448.93983 | E32: 879.125
B33: 75th Percentile | C33: 750.78 | D33: 476.835 | E33: 933.75
B35: Deal Price for Reference | C35: 1136 | D35: 1136 | E35: 1136 | F35: PitchBook: $1,136M deal amount (precise: $1,136,109K)
B36: Deal / PF EBITDA Multiple | E36: 15.2x | F36: $1,136M / $75M pro forma = 15.1x
B38: INTERPRETATION
B39: CCA implies Jagex standalone public trading value of $212M-$832M (EV/Revenue) or $227M-$874M (EV/EBITDA on pro forma).
B40: Deal price of $1.14B represents a significant premium to public comps — expected for a take-private LBO.
B41: Premium to CCA median: ~190% (EV/Revenue) and ~63% (EV/PF EBITDA). Consistent with significant control premium for PE take-private.
B42: Pearl Abyss excluded from EV/EBITDA due to near-zero EBITDA ($5.4M) creating extreme 477x outlier.
B43: Gravity missing EV/Revenue in PitchBook — GRVY trades OTC with limited liquidity.
B44: NCsoft EV/EBITDA of 33x reflects Lineage mobile franchise premium; excluding NCsoft, median drops to ~8.0x.
B45: Note: TTM financials reflect period ending ~Dec 2025, NOT deal-time (May 2024). EBITDA has declined from deal-time $56.4M to $38.3M.
B48: TIGHT PEER SUBSET (Paradox + Frontier + Everplay)
...

Sheet PTA
B1: JAGEX — PRECEDENT TRANSACTION ANALYSIS (PTA)
B2: PitchBook M&A Comps | Downloaded 15-Apr-2026 | Gaming M&A deals 2021-2025
B3: Next Games excluded by user (EV/EBITDA -155x, distressed). 6 comps analyzed.
B5: PRECEDENT TRANSACTIONS
B6: Target | C6: Deal Date | D6: HQ | E6: Acquirer | F6: Deal Type | G6: EV/EBITDA | H6: EV/Rev | I6: Notes
B7: Sybo Games | C7: 24-Jun-2022 | D7: Copenhagen, DK | E7: Miniclip (Tencent) | F7: M&A | G7: 35.49 | H7: N/A | I7: Subway Surfers - hit mobile franchise; strategic premium
B8: Codemasters | C8: 18-Feb-2021 | D8: Southam, UK | E8: Electronic Arts (NAS:EA) | F8: M&A | G8: 29.8 | H8: 8.44 | I8: F1, DiRT racing franchise; strategic acquirer. EV/LTM Adj EBITDA at announcement (14-Dec-2020): £894.9M EV / £30.0M LTM Sep-2020 EBITDA = 29.83x. EV bridge: £945M equity − £50.1M net cash. LTM EBITDA = FY20 £18.2M + H1 FY21 £21.2M − H1 FY20 £9.4M (interim results filed 23-Nov-2020 under RNS 0926G). Cross-checked vs InvestGame.net published 29.8x. The 16.5x figure cited in some sources is the forward FY21 broker-consensus multiple, not trailing.
B9: Climax Studios | C9: 21-Apr-2021 | D9: Portsmouth, UK | E9: Keywords Studios (LON:KWS) | F9: M&A | G9: 13.56 | H9: 5.01 | I9: UK co-development studio
B10: astragon Entertainment | C10: 13-Jan-2022 | D10: Dusseldorf, DE | E10: Everplay Group (LON:EVPL) | F10: M&A | G10: 12.71 | H10: N/A | I10: Simulation games publisher (Construction Sim)
B11: Coffee Stain Gothenburg | C11: 19-Aug-2022 | D11: Gothenburg, SE | E11: Embracer Group (STO:EMBRAC B) | F11: M&A | G11: 2.4 | H11: 2.36 | I11: Satisfactory developer; internal restructuring
B12: Thunderful Group | C12: 30-Sep-2025 | D12: Gothenburg, SE | E12: Atari (PAR:ALATA) | F12: M&A | G12: 0.95 | H12: 0.24 | I12: Distressed Nordic publisher; non-normalized
B14: LEGEND: Light orange = potential outlier (reviewed below)
B16: SUMMARY STATISTICS
B17: Statistic | C17: EV/EBITDA (All 6) | D17: EV/EBITDA (Core 3) | F17: EV/Revenue (All 4) | G17: EV/Revenue (Core 2) | H17: Notes
B18: Mean | C18: 13.608333 | D18: 14.27 | F18: 4.0125 | G18: 6.725
B19: Median | C19: 13.135 | D19: 13.56 | F19: 3.685 | G19: 6.725
B20: 25th Percentile | C20: 4.9775 | D20: 13.135 | F20: 1.83 | G20: 5.8675
B21: 75th Percentile | C21: 15.795 | D21: 15.05 | F21: 5.8675 | G21: 7.5825
B22: Min | C22: 0.95 | D22: 12.71 | F22: 0.24 | G22: 5.01
B23: Max | C23: 35.49 | D23: 16.54 | F23: 8.44 | G23: 8.44
B25: Core set = 3 comps (Codemasters, Climax, astragon) excluding Sybo (35.49x hit-franchise premium) and Coffee Stain (2.40x internal restructuring)
B26: Core EV/Rev set = 2 comps (Codemasters 8.44x, Climax 5.01x) excluding Thunderful 0.24x (distressed) and Coffee Stain 2.36x (internal)
B28: IMPLIED JAGEX VALUATION
B29: Applied to Jagex Financials: | C29: Mult | D29: $M | E29: £M | I29: Basis
B30: Low (25th pct all) | C30: 4.9775 | D30: 373.3125 | E30: 295.64623 | I30: EV/EBITDA × PF $75M
B31: Median (all 6) | C31: 13.135 | D31: 985.125 | E31: 780.17344 | I31: EV/EBITDA × PF $75M
B32: Mean (all 6) | C32: 13.608333 | D32: 1020.625 | E32: 808.2878 | I32: EV/EBITDA × PF $75M
B33: High (75th pct all) | C33: 15.795 | D33: 1184.625 | E33: 938.16821 | I33: EV/EBITDA × PF $75M
B35: Median (core 3) | C35: 13.56 | D35: 1017 | E35: 805.41696 | I35: EV/EBITDA × PF $75M
B36: Mean (core 3) | C36: 14.27 | D36: 1070.25 | E36: 847.5885 | I36: EV/EBITDA × PF $75M
B38: Median (all 6) × Rptd EBITDA | C38: 13.135 | D38: 740.814 | E38: 586.69043 | I38: EV/EBITDA × Rptd $56.4M
B40: Median EV/Rev × Revenue | C40: 3.685 | D40: 695.728 | E40: 550.9844 | I40: EV/Rev × $188.8M
B41: Median EV/Rev (core) × Revenue | C41: 6.725 | D41: 1269.68 | E41: 1005.5278 | I41: EV/Rev × $188.8M
B43: Jagex Deal (reference) | C43: 15.1x | D43: 1136 | E43: 900 | I43: PitchBook: Deal/PF EBITDA 15.1x; Deal/Rptd 20.13x
B45: INTERPRETATION
B46: PTA implies Jagex valuation of $374M-$1,185M (£296M-£938M) at 25th-75th percentile of all 6 comps on pro forma EBITDA basis.
B47: Median-derived implied EV of $985M (£780M) is below deal price of $1,136M (£900M), implying Jagex commanded a ~15% premium to median PTA comp.
B48: Core set analysis (Codemasters, Climax, astragon) yields median 13.56x × $75M = $1,017M (£805M) — still below deal price but much closer to the actual multiple.
B49: Sybo Games (35.49x) represents strategic hit-franchise premium — Miniclip paid for the #1 mobile game globally (Subway Surfers). Not comparable to Jagex's MMORPG model.
B50: Coffee Stain Gothenburg (2.40x) and Thunderful (0.95x) represent internal restructurings and distressed deals. Also not comparable.
...

Sheet DCF
B1: JAGEX — DISCOUNTED CASH FLOW ANALYSIS
B2: Paper DCF with PitchBook-sourced base year | (£ in millions)
B5: KEY ASSUMPTIONS (yellow = editable)
B6: Base Revenue FY2023 (£M) | C6: 149 | D6: PitchBook TTM $188.8M ÷ 1.27
B7: Base Reported EBITDA FY2023 (£M) | C7: 44.4 | D7: PitchBook TTM $56.4M ÷ 1.27
B8: Base Pro Forma EBITDA FY2023 (£M) | C8: 59.4 | D8: PitchBook $75M ÷ 1.263
B9: Revenue Growth Y1-Y2 | C9: 0.08 | D9: Paper: moderate (PitchBook shows 10.5% trailing)
B10: Revenue Growth Y3-Y5 | C10: 0.05 | D10: Paper: mature growth rate
B11: EBITDA Margin (use pro forma basis) | C11: 0.4 | D11: Paper: 39.7% pro forma FY23 ($75M/$188.8M), assume slight expansion
B12: D&A % of Revenue | C12: 0.048 | D12: Derived: PitchBook D&A ≈ £7.1M / £149M = 4.8%
B13: Tax Rate | C13: 0.25 | D13: UK Corporation Tax (standard rate)
B14: CapEx % of Revenue | C14: 0.045 | D14: Derived: intangible investment ~$8.7M/yr (FY23 growth) / $188.8M rev = 4.6%
B15: ΔNWC % of ΔRevenue | C15: 0.05 | D15: Paper: subscription model = modest NWC needs
B16: WACC | C16: 0.1 | D16: Paper: private company, gaming risk premium
B17: Terminal Growth Rate | C17: 0.025 | D17: Paper: long-lived franchise, 25yr track record
B19: PROJECTED UNLEVERED FREE CASH FLOW
C20: FY2024E | D20: FY2025E | E20: FY2026E | F20: FY2027E | G20: FY2028E
B21: Revenue | C21: =C6*(1+C9) -> 160.92 | D21: =C21*(1+C9) -> 173.7936 | E21: =D21*(1+C10) -> 182.48328 | F21: =E21*(1+C10) -> 191.60744 | G21: =F21*(1+C10) -> 201.18782
B22: EBITDA | C22: =C21*C11 -> 64.368 | D22: =D21*C11 -> 69.51744 | E22: =E21*C11 -> 72.993312 | F22: =F21*C11 -> 76.642978 | G22: =G21*C11 -> 80.475126
B23: (-) D&A | C23: =-C21*C12 -> -7.72416 | D23: =-D21*C12 -> -8.3420928 | E23: =-E21*C12 -> -8.7591974 | F23: =-F21*C12 -> -9.1971573 | G23: =-G21*C12 -> -9.6570152
B24: EBIT | C24: =C22+C23 -> 56.64384 | D24: =D22+D23 -> 61.175347 | E24: =E22+E23 -> 64.234115 | F24: =F22+F23 -> 67.44582 | G24: =G22+G23 -> 70.818111
B25: (-) Taxes on EBIT | C25: =-C24*C13 -> -14.16096 | D25: =-D24*C13 -> -15.293837 | E25: =-E24*C13 -> -16.058529 | F25: =-F24*C13 -> -16.861455 | G25: =-G24*C13 -> -17.704528
B26: NOPAT | C26: =C24+C25 -> 42.48288 | D26: =D24+D25 -> 45.88151 | E26: =E24+E25 -> 48.175586 | F26: =F24+F25 -> 50.584365 | G26: =G24+G25 -> 53.113583
B27: (+) D&A Add-back | C27: =-C23 -> 7.72416 | D27: =-D23 -> 8.3420928 | E27: =-E23 -> 8.7591974 | F27: =-F23 -> 9.1971573 | G27: =-G23 -> 9.6570152
B28: (-) CapEx | C28: =-C21*C14 -> -7.2414 | D28: =-D21*C14 -> -7.820712 | E28: =-E21*C14 -> -8.2117476 | F28: =-F21*C14 -> -8.622335 | G28: =-G21*C14 -> -9.0534517
B29: (-) Chg in NWC | C29: =-(C21-C6)*C15 -> -0.596 | D29: =-(D21-C21)*C15 -> -0.64368 | E29: =-(E21-D21)*C15 -> -0.434484 | F29: =-(F21-E21)*C15 -> -0.4562082 | G29: =-(G21-F21)*C15 -> -0.47901861
B30: Unlevered Free Cash Flow | C30: =C26+C27+C28+C29 -> 42.36964 | D30: =D26+D27+D28+D29 -> 45.759211 | E30: =E26+E27+E28+E29 -> 48.288552 | F30: =F26+F27+F28+F29 -> 50.702979 | G30: =G26+G27+G28+G29 -> 53.238128
B31: Discount Factor | C31: =1/(1+C16)^1 -> 0.90909091 | D31: =1/(1+C16)^2 -> 0.82644628 | E31: =1/(1+C16)^3 -> 0.7513148 | F31: =1/(1+C16)^4 -> 0.68301346 | G31: =1/(1+C16)^5 -> 0.62092132
B32: PV of UFCF | C32: =C30*C31 -> 38.517855 | D32: =D30*D31 -> 37.81753 | E32: =E30*E31 -> 36.279904 | F32: =F30*F31 -> 34.630817 | G32: =G30*G31 -> 33.056689
B34: TERMINAL VALUE & ENTERPRISE VALUE
B35: Terminal Value (Gordon Growth) | C35: =G30*(1+C17)/(C16-C17) -> 727.58775 | D35: UFCF_Y5 × (1+g) / (WACC-g)
B36: PV of Terminal Value | C36: =C35*G31 -> 451.77475
B37: Sum of PV of UFCFs | C37: =SUM(C32:G32) -> 180.30279
B38: Implied Enterprise Value (£M) | C38: =C36+C37 -> 632.07754
B39: TV as % of EV | C39: =C36/C38 -> 0.71474577
B40: Implied EV / Pro Forma EBITDA | C40: =C38/C8 -> 10.641036
B41: Deal Price for Reference (£M) | C41: 900 | D41: £900M ($1,136M / 1.2627)
B43: SENSITIVITY: IMPLIED EV (£M) — WACC vs Terminal Growth Rate
B44: WACC \ TGR | C44: 0.015 | D44: 0.02 | E44: 0.025 | F44: 0.03 | G44: 0.035
B45: 0.08 | C45: =C30/(1+$B45)^1+D30/(1+$B45)^2+E30/(1+$B45)^3+F30/(1+$B45)^4+G30/(1+$B45)^5+G30*(1+C$44)/($B45-C$44)/(1+$B45)^5 -> 756.08833 | D45: =C30/(1+$B45)^1+D30/(1+$B45)^2+E30/(1+$B45)^3+F30/(1+$B45)^4+G30/(1+$B45)^5+G30*(1+D$44)/($B45-D$44)/(1+$B45)^5 -> 806.25707 | E45: =C30/(1+$B45)^1+D30/(1+$B45)^2+E30/(1+$B45)^3+F30/(1+$B45)^4+G30/(1+$B45)^5+G30*(1+E$44)/($B45-E$44)/(1+$B45)^5 -> 865.54739 | F45: =C30/(1+$B45)^1+D30/(1+$B45)^2+E30/(1+$B45)^3+F30/(1+$B45)^4+G30/(1+$B45)^5+G30*(1+F$44)/($B45-F$44)/(1+$B45)^5 -> 936.69578 | G45: =C30/(1+$B45)^1+D30/(1+$B45)^2+E30/(1+$B45)^3+F30/(1+$B45)^4+G30/(1+$B45)^5+G30*(1+G$44)/($B45-G$44)/(1+$B45)^5 -> 1023.6549
...

Sheet LBO Model
B1: JAGEX — LBO RETURNS ANALYSIS (PitchBook Actual)
B2: CVC/Haveli from Carlyle | Closed 14-May-2024 | (£M) | FX: 1.263
B4: SOURCES & USES (PitchBook Actual)
B5: Sources | C5: Amount (£M) | D5: Amount ($M) | E5: x EBITDA | F5: % Total
B6: Term Loan (7yr, mat 13-May-2031) | C6: 103.4 | D6: 130.63 | E6: =C6/$C$20 -> 1.7407407 | F6: =C6/C10 -> 0.11488889 | J6: PitchBook Debt Summary: $130.63M TL, SONIA+600, 7yr
B7: Revolving Credit Facility | C7: 28.6 | D7: 36.17 | E7: =C7/$C$20 -> 0.48148148 | F7: =C7/C10 -> 0.031777778 | J7: PitchBook Debt Summary: $36.17M RCF, SONIA+600
B8: Total New Debt | C8: =SUM(C6:C7) -> 132 | D8: =SUM(D6:D7) -> 166.8 | E8: =C8/$C$20 -> 2.2222222 | F8: =C8/C10 -> 0.14666667 | J8: PitchBook: Total New Debt $164.15M
B9: Sponsor Equity (CVC VIII + Haveli) | C9: =C10-C8 -> 768 | D9: =D10-D8 -> 969.2 | E9: =C9/$C$20 -> 12.929293 | F9: =C9/C10 -> 0.85333333 | J9: Residual: Deal Amount − Total Debt
B10: Total Sources = Deal Amount | C10: 900 | D10: 1136 | E10: =C10/59.4 -> 15.151515 | F10: =C10/C10 -> 1 | J10: PitchBook: $1,136,109K; at 1.2627 = £900M (press: £910M)
B12: LENDERS AT ISSUANCE (PitchBook)
B13: Apollo Global Mgmt (Debt Solutions BDC) | C13: $72.02M TL + $19.94M RCF = $91.96M | J13: PitchBook Lenders #4-5
B14: Oaktree Capital Mgmt (Strategic Credit BDC) | C14: $56.53M TL + $15.66M RCF = $72.19M | J14: PitchBook Lenders #6-7
B15: Permira | C15: RCF + TL (amounts not disclosed) | J15: PitchBook Lenders #3, #8
B16: Oaktree Capital Mgmt (Mezzanine) | C16: TL + RCF (amounts not disclosed) | J16: PitchBook Lenders #1-2
B18: OPERATING ASSUMPTIONS (yellow = editable)
B19: Entry EV (£M) | C19: 903 | D19: PitchBook: Implied EV $1.09B ÷ 1.263 → £863M; Deal Amount £903M used
B20: Pro Forma EBITDA at Entry (£M) | C20: 59.4 | D20: PitchBook: $75M ÷ 1.263
B21: Entry Multiple (Deal/PF EBITDA) | C21: =C19/C20 -> 15.20202 | D21: Calculated
B22: Reported EBITDA at Entry (£M) | C22: 44.4 | D22: PitchBook TTM: $56.4M ÷ 1.27
B23: Entry Multiple (Deal/Rptd EBITDA) | C23: =C19/C22 -> 20.337838 | D23: Calculated; PitchBook shows 20.13x
B24: Base Revenue (£M) | C24: 149 | D24: PitchBook TTM: $188.8M ÷ 1.27
B25: Revenue Growth Y1-Y2 | C25: 0.08 | D25: Paper: moderate (trailing 10.5%)
B26: Revenue Growth Y3-Y5 | C26: 0.05 | D26: Paper: mature
B27: EBITDA Margin (Pro Forma basis) | C27: 0.4 | D27: Paper: 39.7% PF FY23 + slight expansion
B28: D&A % Revenue | C28: 0.048 | D28: Derived: PitchBook D&A £7.1M / £149M
B29: Tax Rate | C29: 0.25 | D29: UK Corp Tax
B30: CapEx % Revenue | C30: 0.045 | D30: Derived: intangible investment proxy; matches DCF assumption
B31: ΔNWC % ΔRevenue | C31: 0.05 | D31: Paper
B32: SONIA Rate (at close) | C32: 0.052 | D32: Bank of England: 5.20% (May 7 2024 onward)
B33: Spread (TL & RCF) | C33: 0.06 | D33: PitchBook: SONIA + 600bps
B34: All-in Interest Rate | C34: =C32+C33 -> 0.112 | D34: Calculated: SONIA + Spread
B35: Mandatory Amort (% orig TL) | C35: 0.01 | D35: Paper: 1% p.a. standard
B36: Cash Sweep % | C36: 0.5 | D36: Paper: 50% excess CF
B38: OPERATING MODEL
C39: Entry | D39: Year 1 | E39: Year 2 | F39: Year 3 | G39: Year 4 | H39: Year 5
B40: Revenue | C40: =C24 -> 149 | D40: =C40*(1+C25) -> 160.92 | E40: =D40*(1+C25) -> 173.7936 | F40: =E40*(1+C26) -> 182.48328 | G40: =F40*(1+C26) -> 191.60744 | H40: =G40*(1+C26) -> 201.18782
B41: EBITDA | C41: =C20 -> 59.4 | D41: =D40*C27 -> 64.368 | E41: =E40*C27 -> 69.51744 | F41: =F40*C27 -> 72.993312 | G41: =G40*C27 -> 76.642978 | H41: =H40*C27 -> 80.475126
B42: (-) D&A | C42: =C40*C28 -> 7.152 | D42: =D40*C28 -> 7.72416 | E42: =E40*C28 -> 8.3420928 | F42: =F40*C28 -> 8.7591974 | G42: =G40*C28 -> 9.1971573 | H42: =H40*C28 -> 9.6570152
B43: EBIT | C43: =C41-C42 -> 52.248 | D43: =D41-D42 -> 56.64384 | E43: =E41-E42 -> 61.175347 | F43: =F41-F42 -> 64.234115 | G43: =G41-G42 -> 67.44582 | H43: =H41-H42 -> 70.818111
B44: (-) Interest: Term Loan | C44: =C56*C34 -> 11.5808 | D44: =D56*C34 -> 11.5808 | E44: =E56*C34 -> 9.6944938 | F44: =F56*C34 -> 7.5391467 | G44: =G56*C34 -> 5.1516319 | H44: =H56*C34 -> 2.5286336
...

Sheet Football Field
A1: VALUATION FOOTBALL FIELD — IMPLIED ENTERPRISE VALUE
A2: Summary of all valuation methodologies | Deal Price: $1,136M | FX: 1.2627 GBP/USD (May 2024)
A4: Methodology | B4: Low ($M) | C4: High ($M) | D4: Midpoint ($M) | E4: Deal ($1,136M) | F4: Source / Notes
A5: CCA (EV/EBITDA, PitchBook comps 25th pctl to 75th pctl) | B5: 299 | C5: 933 | D5: =(B5+C5)/2 -> 616 | E5: 1136 | F5: CCA Tab — PitchBook 8 gaming comps, 25th-75th EV/EBITDA (4.0x-12.5x) × $75M PF EBITDA. USD
A6: PTA (EV/EBITDA, PitchBook M&A comps 25th pctl to 75th pctl) | B6: 374 | C6: 1184 | D6: =(B6+C6)/2 -> 779 | E6: 1136 | F6: PTA Tab — PitchBook 6 gaming M&A comps 2021-2025, 25th-75th EV/EBITDA (4.98x-15.79x) × $75M PF EBITDA. USD
A7: DCF (WACC 8.0% - 12.0%, Terminal Growth 1.5% - 3.5%) | B7: 585 | C7: 1293 | D7: =(B7+C7)/2 -> 939 | E7: 1136 | F7: DCF Tab — Sensitivity table: WACC 12%/TGR 1.5% (low) to WACC 8%/TGR 3.5% (high). Converted from £463M-£1,024M at 1.2627
A8: LBO Analysis (Sponsor Returns at 15-18x Exit) | B8: 779 | C8: 1076 | D8: =(B8+C8)/2 -> 927.5 | E8: 1136 | F8: LBO Tab — Range reverse-engineered from the IRR sensitivity table (LBO Model B65:H75): entry prices that yield 15-20% Gross IRR at 15x-18x Exit EV/EBITDA over a 5yr hold. Converted from £617M-£852M at FX 1.2627.
A9: PTA — Live-service / take-private set | B9: =PTA!C71*75 -> 1192.5 | C9: =PTA!C72*75 -> 1515 | D9: =(B9+C9)/2 -> 1353.75 | E9: 1136 | F9: Expanded set: Carlyle/Jagex 2021 + Activision/Zynga/Bungie/Keywords + Codemasters. PTA tab rows 59-64.
A10: DEAL PRICE: $1,136M (~£900M)
A12: Enterprise Value: $1,087M implied EV / $1,136M deal amount | 15.1x Pro Forma EBITDA ($75M)
A13: Deal underwritten at 19.25x Implied EV / Reported EBITDA (20.13x Deal / Reported EBITDA)
A17: CHART DATA (stacked bar: Invisible Base + Range)
A18: Methodology | B18: Low ($M) | C18: High ($M) | D18: Invisible Base | E18: Range (High - Low) | F18: Deal Price
A19: LBO analysis (15% – 20% IRR at 15x – 18x exit) | B19: 779 | C19: 1076 | D19: =B19 -> 779 | E19: =C19-B19 -> 297 | F19: 1136
A20: Discounted cash flow analysis (8.0% – 12.0% WACC) | B20: 585 | C20: 1293 | D20: =B20 -> 585 | E20: =C20-B20 -> 708 | F20: 1136
A21: Precedent transactions analysis (EV / EBITDA) | B21: 374 | C21: 1184 | D21: =B21 -> 374 | E21: =C21-B21 -> 810 | F21: 1136
A22: Comparable companies analysis (EV / EBITDA) | B22: 299 | C22: 933 | D22: =B22 -> 299 | E22: =C22-B22 -> 634 | F22: 1136
A24: CHART VALUES:
A25: CCA: $299M — $933M | PTA: $374M — $1,184M | DCF: $585M — $1,293M | LBO: $779M — $1,076M | Deal: $1,136M
A26: All values converted from £ to $ at 1.2627 GBP/USD (May 2024 average, X-Rates.com) — deal-close FX rate
A28: METHODOLOGY NOTES
A29: Row 9: Live-service / take-private precedent set — uses Microsoft/Activision, Take-Two/Zynga, Sony/Bungie, EQT/Keywords plus the seller precedent (Carlyle/Jagex 2021) plus Codemasters. Median ~19.5x EV/EBITDA × $75M PF EBITDA implies ~$1.46B EV — closer to the deal price than the broader PTA range ($374M-$1,184M).
A30: Row 6 retained for reference. The broader 6-deal PTA understates the implied range because three of the six deals (astragon, Coffee Stain, Thunderful) are small-cap or restructuring transactions not directly comparable to a $1.1B live-service buyout.
A31: No fairness opinion exists for this private-to-private deal. The Football Field serves as the primary cross-method valuation reference. Deal price $1,136M sits at the high end of CCA, near midpoint of the live-service PTA set, and within the DCF range.

Sheet Source Log
B1: SOURCE LOG — ALL DATA CITATIONS
B3: # | C3: Source | D3: Data Points | E3: URL / Reference | F3: Date | G3: Tier
B4: 1 | C4: PitchBook Deal #6 | D4: Deal amount $1.14B, EV $1.09B, PF EBITDA $75M, debt $164.15M, type, status, date, employees, CEO, % acquired | E4: PitchBook Data, Inc. (accessed Apr 2026) | F4: May 2024
B5: 2 | C5: PitchBook Debt Summary | D5: TL $130.63M SONIA+600 7yr mat 13-May-2031; RCF $36.17M SONIA+600 | E5: PitchBook Data, Inc. | F5: May 2024
B6: 3 | C6: PitchBook Investors | D6: CVC Fund VIII (Lead: N.Clarry); Haveli (Lead: B.Sheth) | E6: PitchBook Data, Inc. | F6: Feb 2024
B7: 4 | C7: PitchBook Advisors | D7: GS (CVC+Haveli), Aream/Liberty/MS (Jagex), Apollo/Oaktree (debt), L&W/K&E (legal) | E7: PitchBook Data, Inc. | F7: 2024
B8: 5 | C8: PitchBook Sellers/Exiters | D8: Carlyle full exit $1.14B, CP VII + CETP IV, 100% sold | E8: PitchBook Data, Inc. | F8: 2024
B9: 6 | C9: PitchBook Lenders | D9: Apollo $91.96M, Oaktree $72.19M, Permira (undisclosed) | E9: PitchBook Data, Inc. | F9: 2024
B10: 7 | C10: PitchBook Financials TTM | D10: Rev $188.8M, GP $161.3M, EBITDA $56.4M, EBIT $47.4M, NI $48.9M, BS full | E10: PitchBook Data, Inc. (TTM Dec 2023) | F10: 2024
B11: 8 | C11: PitchBook Deal Multiples | D11: EV/EBITDA 19.25x, EV/Rev 5.76x, Deal/EBITDA 20.13x, Debt/EBITDA 2.91x | E11: PitchBook Data, Inc. | F11: 2024
B12: 9 | C12: PitchBook Ratios | D12: EBITDA margin 29.90%, rev growth 10.51%, current ratio 2.63x | E12: PitchBook Data, Inc. | F12: 2024
B13: 10 | C13: Carlyle PR | D13: Deal overview, advisors, subs 2.4M, employees 700 | E13: carlyle.com | F13: Feb 9 2024
B14: 11 | C14: CVC PR | D14: Deal confirmation, franchise details | E14: cvc.com | F14: Feb 9 2024
B15: 12 | C15: Jagex PR | D15: Deal confirmation, record subs, $1.5B lifetime rev | E15: jagex.com | F15: Feb 9 2024
... B31: 28 | C31: PitchBook M&A Comps (PTA) | D31: Sybo, Codemasters, Climax, astragon, Coffee Stain, Thunderful — EV/EBITDA & EV/Rev multiples | E31: PitchBook Data, Inc. (MnA Comps Tab) | F31: Apr 15 2026
B33: PRIMARY SOURCES (Tier 1 — Companies House)
B34: 29 | C34: Companies House — Jagex Ltd (#03982706) | D34: FY2023 accounts (filed 13-Mar-2025), FY2024 accounts (filed 4-Jun-2025), FY2022 accounts (filed 4-Apr-2024) | E34: https://find-and-update.company-information.service.gov.uk/company/03982706/filing-history | F34: Apr 2024 - Jun 2025 | G34: Tier 1
B35: 30 | C35: Companies House — Jagex Charges Register | D35: Charge 0004 (Lucid 7-May-2021, satisfied 15-May-2024); Charge 0005 (Kroll 20-Jun-2023, satisfied); Charge 0006 (Kroll 10-Sep-2024, outstanding) | E35: https://find-and-update.company-information.service.gov.uk/company/03982706/charges | F35: May 2021 - Sep 2024 | G35: Tier 1
B36: 31 | C36: Companies House — Janus Bidco Limited (#15451932) | D36: Inc. 30-Jan-2024; MR01 charge created 25-Apr-2024 (40pp); SH01 share allotment 14-May-2024 in USD; consolidated FY24 accounts filed 7-Oct-2025 (75pp) | E36: https://find-and-update.company-information.service.gov.uk/company/15451932/filing-history | F36: Jan 2024 - Oct 2025 | G36: Tier 1
B37: 32 | C37: Companies House — Janus Midco Limited (#15451988) | D37: Intermediate holdco; Inc. 30-Jan-2024 | E37: https://find-and-update.company-information.service.gov.uk/company/15451988 | F37: Jan 2024 | G37: Tier 1
B38: 33 | C38: Companies House — Janus UK Topco Ltd (FC041396, Jersey) | D38: Inc. 13-Mar-2024; directors Lambkin & Motajo | E38: North Data: northdata.com/Janus+UK+Topco+Ltd | F38: Mar 2024 | G38: Tier 1
B39: 34 | C39: Carlyle Group press release — Jagex sale | D39: Deal announcement; advisors Morgan Stanley + Aream & Co (sell-side); Goldman (buy-side); Carlyle Partners VII + CETP IV; "Terms not disclosed" | E39: https://www.carlyle.com/media-room/news-release-archive/carlyle-agrees-to-sell-jagex-to-cvc-capital-partners-and-haveli | F39: 9-Feb-2024 | G39: Tier 2
B40: 35 | C40: CVC Capital Partners press release | D40: Deal confirmation; Fund VIII; "20+ year history of leadership in live service gaming" | E40: https://www.cvc.com/media/news/2024/2024-02-09-carlyle-agrees-to-sell-jagex-to-cvc-capital-partners-and-haveli-investments/ | F40: 9-Feb-2024 | G40: Tier 2
B41: 36 | C41: Carlyle Group press release — 2021 Jagex acquisition | D41: Carlyle's entry; CP VII + CETP IV equity sources; deal price NOT disclosed in Carlyle press release. $530M entry used in model is Macarthur Fortune's 2020 price as flat-hold proxy (see row 42). | E41: https://www.carlyle.com/media-room/news-release-archive/carlyle-group-acquires-jagex-leading-online-video-game-company-and | F41: 25-Jan-2021 | G41: Tier 2
B42: 37 | C42: Macarthur Fortune Holding LLC press release | D42: Acquisition of Jagex by Macarthur Fortune from Shanghai Hongtou / Shanghai Fukong for $530M — CONFIRMED (this is the 2020 deal, not Carlyle 2021). Carlyle's January 2021 price was never officially disclosed; $530M used as flat-hold proxy. | E42: https://www.prnewswire.com/news-releases/platinum-fortune-acquires-jagex-for-530-million-301050848.html | F42: 1-May-2020 | G42: Tier 2
B43: 38 | C43: Latham & Watkins (CVC counsel) | D43: Deal counsel team; Suneel Basson-Bhatoa (corporate); finance partners team confirms debt was raised | E43: https://www.lw.com/en/news/2024/02/latham-advises-cvc-capital-partners-on-the-acquisition-of-jagex | F43: Feb 2024 | G43: Tier 2
B44: 39 | C44: Kirkland & Ellis (Carlyle counsel) | D44: Deal counsel team; David Higgins (corporate); Jerome Hoyle (debt finance — confirms repayment workstream) | E44: https://www.kirkland.com/news/press-release/2024/02/kirkland-advises-carlyle-on-sale-of-jagex | F44: Feb 2024 | G44: Tier 2
B45: 40 | C45: Kirkland & Ellis — 2021 Jagex acquisition counsel | D45: Carlyle 2021 acquisition legal team | E45: https://www.kirkland.com/news/press-release/2021/01/kirkland-represents-the-carlyle-group-on-jagex | F45: Jan 2021 | G45: Tier 2
... B53: 48 | C53: Newzoo PC & Console Gaming Report 2024 | D53: 67% PC player-hours on titles ≥6 years old; live-service / GaaS market context | E53: newzoo.com/resources/trend-reports | F53: 2024 | G53: Tier 3
B56: SOURCE TIER LEGEND
B57: Tier 1 (definitive): SEC filings, Companies House full audited accounts, regulatory filings | Tier 2 (authoritative): Sponsor PRs, banker fairness opinions, rating agency reports, IR materials | Tier 3 (high-quality secondary): FT/Bloomberg/Reuters/WSJ deal reporting, PitchBook, Mergermarket | Tier 4 (with caution): Trade press (PE Insights, GamesIndustry.biz, Telegraph) | Tier 5 (contextual): Wikipedia, Crunchbase, blog posts
